Workbook

Sheet Exhibiciones 
C1: Formato para el registro de las exhibiciones de pasillos calzado | V1: Código: MS-AUE/02-03
V2: Versión: 001
C3: Periodo de evaluación: | O3: Del 29 al 03 de Julio del 2026 | V3: Vigencia a partir : Mayo 2022
A4: ECATEPEC | C4: Nave | D4: Catalogo | E4: Pasillo | F4: Modelos por Pasillo | G4: Calzado no exhibido | H4: Calzado sin elastico y/o suelto y/o mal amrrado | I4: Calzado blanco o claro, sin playo, playo roto | J4: Calzado no exhibido correctamente | K4: Calzado sucio | L4: Calzado maltratado / dañado | M4: Calzado mal agujetado | N4: Pie izquierdo | O4: Sin relleno autorizado | P4: Sin talla autorizada | Q4: Calzado sin rotacion | R4: Pasillo alineado | S4: Total de areas de oportunidad | T4: Total de areas de oportunidad RECUPERADAS | U4: Nomina | V4: Nombre | W4: % de eficiencia | X4: % de RECUPERACION | Y4: NO MODIFICAR ESTA COLUMNA NI OCULTAR | AD4: ESTAS COLUMNAS NO SE DEBEN MODIFICAR SOLO OCULTAR
A5: SEMANA 26 | B5: Lunes | C5: A | D5: Botas | E5: 15 | F5: 48 | G5: 0 | H5: 0 | I5: 0 | J5: 0 | K5: 0 | L5: 0 | M5: 0 | N5: 0 | O5: 0 | P5: 0 | Q5: 0 | R5: SI | S5: =IF(F5="-","",SUM(G5:Q5)) -> 0 | T5: 0 | U5: 144695 | V5: =IFERROR(VLOOKUP(U5,'Plantilla y Concentrado'!$B$4:$C$811,2,0),"") -> Alvarez Becerra Emiliano | W5: =IF(S5=0,1,IF(S5>AD5,(1-AE5),IF(S5<AD5,1))) -> 1 | X5: =IF(OR(S5=0,S5=""),"-",T5/S5) -> - | Y5: =IF(T5>S5,"SI") -> 0 | Z5: Solo colocar los pasillos evaluados, si algun pasillo se encuentra en cuadraje o movimiento no colocar | AD5: =IF(F5="-","",F5*0.021) -> 1.008 | AE5: =IF(S5=0,"-",IF(S5<AD5,(S5/100),((S5-AD5)/100))) -> - | AF5: =G5 -> 0 | AG5: =SUM(H5:Q5) -> 0
C6: A | D6: Botas | E6: 16 | F6: 33 | G6: 0 | H6: 0 | I6: 0 | J6: 0 | K6: 0 | L6: 0 | M6: 0 | N6: 0 | O6: 0 | P6: 0 | Q6: 0 | R6: SI | S6: =IF(F6="-","",SUM(G6:Q6)) -> 0 | T6: 0 | U6: 144695 | V6: =IFERROR(VLOOKUP(U6,'Plantilla y Concentrado'!$B$4:$C$811,2,0),"") -> Alvarez Becerra Emiliano | W6: =IF(S6=0,1,IF(S6>AD6,(1-AE6),IF(S6<AD6,1))) -> 1 | X6: =IF(OR(S6=0,S6=""),"-",T6/S6) -> - | Y6: =IF(T6>S6,"SI") -> 0 | AD6: =IF(F6="-","",F6*0.021) -> 0.693 | AE6: =IF(S6=0,"-",IF(S6<AD6,(S6/100),((S6-AD6)/100))) -> - | AF6: =G6 -> 0 | AG6: =SUM(H6:Q6) -> 0
C7: A | D7: Botas | E7: 17 | F7: 43 | G7: 0 | H7: 0 | I7: 0 | J7: 0 | K7: 0 | L7: 0 | M7: 0 | N7: 0 | O7: 0 | P7: 0 | Q7: 0 | R7: SI | S7: =IF(F7="-","",SUM(G7:Q7)) -> 0 | T7: 0 | U7: 144695 | V7: =IFERROR(VLOOKUP(U7,'Plantilla y Concentrado'!$B$4:$C$811,2,0),"") -> Alvarez Becerra Emiliano | W7: =IF(S7=0,1,IF(S7>AD7,(1-AE7),IF(S7<AD7,1))) -> 1 | X7: =IF(OR(S7=0,S7=""),"-",T7/S7) -> - | Y7: =IF(T7>S7,"SI") -> 0 | AD7: =IF(F7="-","",F7*0.021) -> 0.903 | AE7: =IF(S7=0,"-",IF(S7<AD7,(S7/100),((S7-AD7)/100))) -> - | AF7: =G7 -> 0 | AG7: =SUM(H7:Q7) -> 0
C8: A | D8: Botas | E8: 18 | F8: 41 | G8: 0 | H8: 0 | I8: 0 | J8: 0 | K8: 0 | L8: 0 | M8: 0 | N8: 0 | O8: 0 | P8: 0 | Q8: 0 | R8: SI | S8: =IF(F8="-","",SUM(G8:Q8)) -> 0 | T8: 0 | U8: 144695 | V8: =IFERROR(VLOOKUP(U8,'Plantilla y Concentrado'!$B$4:$C$811,2,0),"") -> Alvarez Becerra Emiliano | W8: =IF(S8=0,1,IF(S8>AD8,(1-AE8),IF(S8<AD8,1))) -> 1 | X8: =IF(OR(S8=0,S8=""),"-",T8/S8) -> - | Y8: =IF(T8>S8,"SI") -> 0 | AD8: =IF(F8="-","",F8*0.021) -> 0.861 | AE8: =IF(S8=0,"-",IF(S8<AD8,(S8/100),((S8-AD8)/100))) -> - | AF8: =G8 -> 0 | AG8: =SUM(H8:Q8) -> 0
C9: A | D9: Botas | E9: 19 | F9: 55 | G9: 0 | H9: 0 | I9: 0 | J9: 0 | K9: 0 | L9: 0 | M9: 0 | N9: 0 | O9: 0 | P9: 0 | Q9: 0 | R9: SI | S9: =IF(F9="-","",SUM(G9:Q9)) -> 0 | T9: 0 | U9: 144695 | V9: =IFERROR(VLOOKUP(U9,'Plantilla y Concentrado'!$B$4:$C$811,2,0),"") -> Alvarez Becerra Emiliano | W9: =IF(S9=0,1,IF(S9>AD9,(1-AE9),IF(S9<AD9,1))) -> 1 | X9: =IF(OR(S9=0,S9=""),"-",T9/S9) -> - | Y9: =IF(T9>S9,"SI") -> 0 | AD9: =IF(F9="-","",F9*0.021) -> 1.155 | AE9: =IF(S9=0,"-",IF(S9<AD9,(S9/100),((S9-AD9)/100))) -> - | AF9: =G9 -> 0 | AG9: =SUM(H9:Q9) -> 0
C10: A | D10: Botas | E10: 20 | F10: 43 | G10: 0 | H10: 0 | I10: 0 | J10: 0 | K10: 0 | L10: 0 | M10: 0 | N10: 0 | O10: 0 | P10: 0 | Q10: 0 | R10: SI | S10: =IF(F10="-","",SUM(G10:Q10)) -> 0 | T10: 0 | U10: 144695 | V10: =IFERROR(VLOOKUP(U10,'Plantilla y Concentrado'!$B$4:$C$811,2,0),"") -> Alvarez Becerra Emiliano | W10: =IF(S10=0,1,IF(S10>AD10,(1-AE10),IF(S10<AD10,1))) -> 1 | X10: =IF(OR(S10=0,S10=""),"-",T10/S10) -> - | Y10: =IF(T10>S10,"SI") -> 0 | AD10: =IF(F10="-","",F10*0.021) -> 0.903 | AE10: =IF(S10=0,"-",IF(S10<AD10,(S10/100),((S10-AD10)/100))) -> - | AF10: =G10 -> 0 | AG10: =SUM(H10:Q10) -> 0
C11: A | D11: Botas | E11: 21 | F11: 33 | G11: 0 | H11: 0 | I11: 0 | J11: 0 | K11: 0 | L11: 0 | M11: 0 | N11: 0 | O11: 0 | P11: 0 | Q11: 0 | R11: SI | S11: =IF(F11="-","",SUM(G11:Q11)) -> 0 | T11: 0 | U11: 136867 | V11: =IFERROR(VLOOKUP(U11,'Plantilla y Concentrado'!$B$4:$C$811,2,0),"") -> Barba Ramirez Jatziri Lizeth | W11: =IF(S11=0,1,IF(S11>AD11,(1-AE11),IF(S11<AD11,1))) -> 1 | X11: =IF(OR(S11=0,S11=""),"-",T11/S11) -> - | Y11: =IF(T11>S11,"SI") -> 0 | AD11: =IF(F11="-","",F11*0.021) -> 0.693 | AE11: =IF(S11=0,"-",IF(S11<AD11,(S11/100),((S11-AD11)/100))) -> - | AF11: =G11 -> 0 | AG11: =SUM(H11:Q11) -> 0
C12: A | D12: Botas | E12: 22 | F12: 50 | G12: 0 | H12: 0 | I12: 0 | J12: 0 | K12: 0 | L12: 0 | M12: 0 | N12: 0 | O12: 0 | P12: 0 | Q12: 0 | R12: - | S12: =IF(F12="-","",SUM(G12:Q12)) -> 0 | T12: 0 | U12: 136867 | V12: =IFERROR(VLOOKUP(U12,'Plantilla y Concentrado'!$B$4:$C$811,2,0),"") -> Barba Ramirez Jatziri Lizeth | W12: =IF(S12=0,1,IF(S12>AD12,(1-AE12),IF(S12<AD12,1))) -> 1 | X12: =IF(OR(S12=0,S12=""),"-",T12/S12) -> - | Y12: =IF(T12>S12,"SI") -> 0 | AD12: =IF(F12="-","",F12*0.021) -> 1.05 | AE12: =IF(S12=0,"-",IF(S12<AD12,(S12/100),((S12-AD12)/100))) -> - | AF12: =G12 -> 0 | AG12: =SUM(H12:Q12) -> 0
C13: A | D13: Botas | E13: 23 | F13: 46 | G13: 0 | H13: 0 | I13: 0 | J13: 0 | K13: 0 | L13: 0 | M13: 0 | N13: 0 | O13: 0 | P13: 0 | Q13: 0 | R13: - | S13: =IF(F13="-","",SUM(G13:Q13)) -> 0 | T13: 0 | U13: 136867 | V13: =IFERROR(VLOOKUP(U13,'Plantilla y Concentrado'!$B$4:$C$811,2,0),"") -> Barba Ramirez Jatziri Lizeth | W13: =IF(S13=0,1,IF(S13>AD13,(1-AE13),IF(S13<AD13,1))) -> 1 | X13: =IF(OR(S13=0,S13=""),"-",T13/S13) -> - | Y13: =IF(T13>S13,"SI") -> 0 | AD13: =IF(F13="-","",F13*0.021) -> 0.966 | AE13: =IF(S13=0,"-",IF(S13<AD13,(S13/100),((S13-AD13)/100))) -> - | AF13: =G13 -> 0 | AG13: =SUM(H13:Q13) -> 0
C14: A | D14: Botas | E14: 24 | F14: 34 | G14: 0 | H14: 0 | I14: 0 | J14: 0 | K14: 0 | L14: 0 | M14: 0 | N14: 0 | O14: 0 | P14: 0 | Q14: 0 | R14: - | S14: =IF(F14="-","",SUM(G14:Q14)) -> 0 | T14: 0 | U14: 136867 | V14: =IFERROR(VLOOKUP(U14,'Plantilla y Concentrado'!$B$4:$C$811,2,0),"") -> Barba Ramirez Jatziri Lizeth | W14: =IF(S14=0,1,IF(S14>AD14,(1-AE14),IF(S14<AD14,1))) -> 1 | X14: =IF(OR(S14=0,S14=""),"-",T14/S14) -> - | Y14: =IF(T14>S14,"SI") -> 0 | AD14: =IF(F14="-","",F14*0.021) -> 0.714 | AE14: =IF(S14=0,"-",IF(S14<AD14,(S14/100),((S14-AD14)/100))) -> - | AF14: =G14 -> 0 | AG14: =SUM(H14:Q14) -> 0
C15: A | D15: Botas | E15: 25 | F15: 37 | G15: 0 | H15: 0 | I15: 0 | J15: 0 | K15: 0 | L15: 0 | M15: 0 | N15: 0 | O15: 0 | P15: 0 | Q15: 0 | R15: - | S15: =IF(F15="-","",SUM(G15:Q15)) -> 0 | T15: 0 | U15: 158001 | V15: =IFERROR(VLOOKUP(U15,'Plantilla y Concentrado'!$B$4:$C$811,2,0),"") -> Nuñez Garcia Clarissa Naomi | W15: =IF(S15=0,1,IF(S15>AD15,(1-AE15),IF(S15<AD15,1))) -> 1 | X15: =IF(OR(S15=0,S15=""),"-",T15/S15) -> - | Y15: =IF(T15>S15,"SI") -> 0 | AD15: =IF(F15="-","",F15*0.021) -> 0.777 | AE15: =IF(S15=0,"-",IF(S15<AD15,(S15/100),((S15-AD15)/100))) -> - | AF15: =G15 -> 0 | AG15: =SUM(H15:Q15) -> 0
C16: A | D16: Botas | E16: 26 | F16: 43 | G16: 0 | H16: 0 | I16: 0 | J16: 0 | K16: 0 | L16: 0 | M16: 0 | N16: 0 | O16: 0 | P16: 0 | Q16: 0 | R16: - | S16: =IF(F16="-","",SUM(G16:Q16)) -> 0 | T16: 0 | U16: 151630 | V16: =IFERROR(VLOOKUP(U16,'Plantilla y Concentrado'!$B$4:$C$811,2,0),"") -> Muñoz Lara Karla Paola | W16: =IF(S16=0,1,IF(S16>AD16,(1-AE16),IF(S16<AD16,1))) -> 1 | X16: =IF(OR(S16=0,S16=""),"-",T16/S16) -> - | Y16: =IF(T16>S16,"SI") -> 0 | AD16: =IF(F16="-","",F16*0.021) -> 0.903 | AE16: =IF(S16=0,"-",IF(S16<AD16,(S16/100),((S16-AD16)/100))) -> - | AF16: =G16 -> 0 | AG16: =SUM(H16:Q16) -> 0
C17: A | D17: Botas | E17: 27 | F17: 48 | G17: 0 | H17: 0 | I17: 0 | J17: 0 | K17: 0 | L17: 0 | M17: 0 | N17: 0 | O17: 0 | P17: 0 | Q17: 0 | R17: - | S17: =IF(F17="-","",SUM(G17:Q17)) -> 0 | T17: 0 | U17: 151630 | V17: =IFERROR(VLOOKUP(U17,'Plantilla y Concentrado'!$B$4:$C$811,2,0),"") -> Muñoz Lara Karla Paola | W17: =IF(S17=0,1,IF(S17>AD17,(1-AE17),IF(S17<AD17,1))) -> 1 | X17: =IF(OR(S17=0,S17=""),"-",T17/S17) -> - | Y17: =IF(T17>S17,"SI") -> 0 | AD17: =IF(F17="-","",F17*0.021) -> 1.008 | AE17: =IF(S17=0,"-",IF(S17<AD17,(S17/100),((S17-AD17)/100))) -> - | AF17: =G17 -> 0 | AG17: =SUM(H17:Q17) -> 0
... C22: A | D22: Botas | E22: 3 | F22: 32 | G22: 0 | H22: 0 | I22: 0 | J22: 0 | K22: 0 | L22: 0 | M22: 0 | N22: 0 | O22: 0 | P22: 0 | Q22: 0 | R22: - | S22: =IF(F22="-","",SUM(G22:Q22)) -> 0 | T22: 0 | U22: 151630 | V22: =IFERROR(VLOOKUP(U22,'Plantilla y Concentrado'!$B$4:$C$811,2,0),"") -> Muñoz Lara Karla Paola | W22: =IF(S22=0,1,IF(S22>AD22,(1-AE22),IF(S22<AD22,1))) -> 1 | X22: =IF(OR(S22=0,S22=""),"-",T22/S22) -> - | Y22: =IF(T22>S22,"SI") -> 0 | AD22: =IF(F22="-","",F22*0.021) -> 0.672 | AE22: =IF(S22=0,"-",IF(S22<AD22,(S22/100),((S22-AD22)/100))) -> - | AF22: =G22 -> 0 | AG22: =SUM(H22:Q22) -> 0
C23: A | D23: Botas | F23: - | G23: 0 | H23: 0 | I23: 0 | J23: 0 | K23: 0 | L23: 0 | M23: 0 | N23: 0 | O23: 0 | P23: 0 | Q23: 0 | R23: - | S23: =IF(F23="-","",SUM(G23:Q23)) | T23: 0 | V23: =IFERROR(VLOOKUP(U23,'Plantilla y Concentrado'!$B$4:$C$811,2,0),"") | W23: =IF(S23=0,1,IF(S23>AD23,(1-AE23),IF(S23<AD23,1))) -> 0 | X23: =IF(OR(S23=0,S23=""),"-",T23/S23) -> - | Y23: =IF(T23>S23,"SI") -> 0 | AD23: =IF(F23="-","",F23*0.021) | AE23: =IF(S23=0,"-",IF(S23<AD23,(S23/100),((S23-AD23)/100))) -> #VALUE! | AF23: =G23 -> 0 | AG23: =SUM(H23:Q23) -> 0
C24: A | D24: Botas | F24: - | G24: 0 | H24: 0 | I24: 0 | J24: 0 | K24: 0 | L24: 0 | M24: 0 | N24: 0 | O24: 0 | P24: 0 | Q24: 0 | R24: - | S24: =IF(F24="-","",SUM(G24:Q24)) | T24: 0 | V24: =IFERROR(VLOOKUP(U24,'Plantilla y Concentrado'!$B$4:$C$811,2,0),"") | W24: =IF(S24=0,1,IF(S24>AD24,(1-AE24),IF(S24<AD24,1))) -> 0 | X24: =IF(OR(S24=0,S24=""),"-",T24/S24) -> - | Y24: =IF(T24>S24,"SI") -> 0 | AD24: =IF(F24="-","",F24*0.021) | AE24: =IF(S24=0,"-",IF(S24<AD24,(S24/100),((S24-AD24)/100))) -> #VALUE! | AF24: =G24 -> 0 | AG24: =SUM(H24:Q24) -> 0
C25: A | D25: Botas | F25: - | G25: 0 | H25: 0 | I25: 0 | J25: 0 | K25: 0 | L25: 0 | M25: 0 | N25: 0 | O25: 0 | P25: 0 | Q25: 0 | R25: - | S25: =IF(F25="-","",SUM(G25:Q25)) | T25: 0 | V25: =IFERROR(VLOOKUP(U25,'Plantilla y Concentrado'!$B$4:$C$811,2,0),"") | W25: =IF(S25=0,1,IF(S25>AD25,(1-AE25),IF(S25<AD25,1))) -> 0 | X25: =IF(OR(S25=0,S25=""),"-",T25/S25) -> - | Y25: =IF(T25>S25,"SI") -> 0 | AD25: =IF(F25="-","",F25*0.021) | AE25: =IF(S25=0,"-",IF(S25<AD25,(S25/100),((S25-AD25)/100))) -> #VALUE! | AF25: =G25 -> 0 | AG25: =SUM(H25:Q25) -> 0
C26: A | D26: Botas | F26: - | G26: 0 | H26: 0 | I26: 0 | J26: 0 | K26: 0 | L26: 0 | M26: 0 | N26: 0 | O26: 0 | P26: 0 | Q26: 0 | R26: - | S26: =IF(F26="-","",SUM(G26:Q26)) | T26: 0 | V26: =IFERROR(VLOOKUP(U26,'Plantilla y Concentrado'!$B$4:$C$811,2,0),"") | W26: =IF(S26=0,1,IF(S26>AD26,(1-AE26),IF(S26<AD26,1))) -> 0 | X26: =IF(OR(S26=0,S26=""),"-",T26/S26) -> - | Y26: =IF(T26>S26,"SI") -> 0 | AD26: =IF(F26="-","",F26*0.021) | AE26: =IF(S26=0,"-",IF(S26<AD26,(S26/100),((S26-AD26)/100))) -> #VALUE! | AF26: =G26 -> 0 | AG26: =SUM(H26:Q26) -> 0
C27: A | D27: Botas | F27: - | G27: 0 | H27: 0 | I27: 0 | J27: 0 | K27: 0 | L27: 0 | M27: 0 | N27: 0 | O27: 0 | P27: 0 | Q27: 0 | R27: - | S27: =IF(F27="-","",SUM(G27:Q27)) | T27: 0 | V27: =IFERROR(VLOOKUP(U27,'Plantilla y Concentrado'!$B$4:$C$811,2,0),"") | W27: =IF(S27=0,1,IF(S27>AD27,(1-AE27),IF(S27<AD27,1))) -> 0 | X27: =IF(OR(S27=0,S27=""),"-",T27/S27) -> - | Y27: =IF(T27>S27,"SI") -> 0 | AD27: =IF(F27="-","",F27*0.021) | AE27: =IF(S27=0,"-",IF(S27<AD27,(S27/100),((S27-AD27)/100))) -> #VALUE! | AF27: =G27 -> 0 | AG27: =SUM(H27:Q27) -> 0
C28: A | D28: Botas | F28: - | G28: 0 | H28: 0 | I28: 0 | J28: 0 | K28: 0 | L28: 0 | M28: 0 | N28: 0 | O28: 0 | P28: 0 | Q28: 0 | R28: - | S28: =IF(F28="-","",SUM(G28:Q28)) | T28: 0 | V28: =IFERROR(VLOOKUP(U28,'Plantilla y Concentrado'!$B$4:$C$811,2,0),"") | W28: =IF(S28=0,1,IF(S28>AD28,(1-AE28),IF(S28<AD28,1))) -> 0 | X28: =IF(OR(S28=0,S28=""),"-",T28/S28) -> - | Y28: =IF(T28>S28,"SI") -> 0 | AD28: =IF(F28="-","",F28*0.021) | AE28: =IF(S28=0,"-",IF(S28<AD28,(S28/100),((S28-AD28)/100))) -> #VALUE! | AF28: =G28 -> 0 | AG28: =SUM(H28:Q28) -> 0
C29: A | D29: Botas | F29: - | G29: 0 | H29: 0 | I29: 0 | J29: 0 | K29: 0 | L29: 0 | M29: 0 | N29: 0 | O29: 0 | P29: 0 | Q29: 0 | R29: - | S29: =IF(F29="-","",SUM(G29:Q29)) | T29: 0 | V29: =IFERROR(VLOOKUP(U29,'Plantilla y Concentrado'!$B$4:$C$811,2,0),"") | W29: =IF(S29=0,1,IF(S29>AD29,(1-AE29),IF(S29<AD29,1))) -> 0 | X29: =IF(OR(S29=0,S29=""),"-",T29/S29) -> - | Y29: =IF(T29>S29,"SI") -> 0 | AD29: =IF(F29="-","",F29*0.021) | AE29: =IF(S29=0,"-",IF(S29<AD29,(S29/100),((S29-AD29)/100))) -> #VALUE! | AF29: =G29 -> 0 | AG29: =SUM(H29:Q29) -> 0
C30: A | D30: Botas | F30: - | G30: 0 | H30: 0 | I30: 0 | J30: 0 | K30: 0 | L30: 0 | M30: 0 | N30: 0 | O30: 0 | P30: 0 | Q30: 0 | R30: - | S30: =IF(F30="-","",SUM(G30:Q30)) | T30: 0 | V30: =IFERROR(VLOOKUP(U30,'Plantilla y Concentrado'!$B$4:$C$811,2,0),"") | W30: =IF(S30=0,1,IF(S30>AD30,(1-AE30),IF(S30<AD30,1))) -> 0 | X30: =IF(OR(S30=0,S30=""),"-",T30/S30) -> - | Y30: =IF(T30>S30,"SI") -> 0 | AD30: =IF(F30="-","",F30*0.021) | AE30: =IF(S30=0,"-",IF(S30<AD30,(S30/100),((S30-AD30)/100))) -> #VALUE! | AF30: =G30 -> 0 | AG30: =SUM(H30:Q30) -> 0
C31: A | D31: Botas | F31: - | G31: 0 | H31: 0 | I31: 0 | J31: 0 | K31: 0 | L31: 0 | M31: 0 | N31: 0 | O31: 0 | P31: 0 | Q31: 0 | R31: - | S31: =IF(F31="-","",SUM(G31:Q31)) | T31: 0 | V31: =IFERROR(VLOOKUP(U31,'Plantilla y Concentrado'!$B$4:$C$811,2,0),"") | W31: =IF(S31=0,1,IF(S31>AD31,(1-AE31),IF(S31<AD31,1))) -> 0 | X31: =IF(OR(S31=0,S31=""),"-",T31/S31) -> - | Y31: =IF(T31>S31,"SI") -> 0 | AD31: =IF(F31="-","",F31*0.021) | AE31: =IF(S31=0,"-",IF(S31<AD31,(S31/100),((S31-AD31)/100))) -> #VALUE! | AF31: =G31 -> 0 | AG31: =SUM(H31:Q31) -> 0
C32: A | D32: Botas | F32: - | G32: 0 | H32: 0 | I32: 0 | J32: 0 | K32: 0 | L32: 0 | M32: 0 | N32: 0 | O32: 0 | P32: 0 | Q32: 0 | R32: - | S32: =IF(F32="-","",SUM(G32:Q32)) | T32: 0 | V32: =IFERROR(VLOOKUP(U32,'Plantilla y Concentrado'!$B$4:$C$811,2,0),"") | W32: =IF(S32=0,1,IF(S32>AD32,(1-AE32),IF(S32<AD32,1))) -> 0 | X32: =IF(OR(S32=0,S32=""),"-",T32/S32) -> - | Y32: =IF(T32>S32,"SI") -> 0 | AD32: =IF(F32="-","",F32*0.021) | AE32: =IF(S32=0,"-",IF(S32<AD32,(S32/100),((S32-AD32)/100))) -> #VALUE! | AF32: =G32 -> 0 | AG32: =SUM(H32:Q32) -> 0
C33: A | D33: Botas | F33: - | G33: 0 | H33: 0 | I33: 0 | J33: 0 | K33: 0 | L33: 0 | M33: 0 | N33: 0 | O33: 0 | P33: 0 | Q33: 0 | R33: - | S33: =IF(F33="-","",SUM(G33:Q33)) | T33: 0 | V33: =IFERROR(VLOOKUP(U33,'Plantilla y Concentrado'!$B$4:$C$811,2,0),"") | W33: =IF(S33=0,1,IF(S33>AD33,(1-AE33),IF(S33<AD33,1))) -> 0 | X33: =IF(OR(S33=0,S33=""),"-",T33/S33) -> - | Y33: =IF(T33>S33,"SI") -> 0 | AD33: =IF(F33="-","",F33*0.021) | AE33: =IF(S33=0,"-",IF(S33<AD33,(S33/100),((S33-AD33)/100))) -> #VALUE! | AF33: =G33 -> 0 | AG33: =SUM(H33:Q33) -> 0
C34: A | D34: Botas | F34: - | G34: 0 | H34: 0 | I34: 0 | J34: 0 | K34: 0 | L34: 0 | M34: 0 | N34: 0 | O34: 0 | P34: 0 | Q34: 0 | R34: - | S34: =IF(F34="-","",SUM(G34:Q34)) | T34: 0 | V34: =IFERROR(VLOOKUP(U34,'Plantilla y Concentrado'!$B$4:$C$811,2,0),"") | W34: =IF(S34=0,1,IF(S34>AD34,(1-AE34),IF(S34<AD34,1))) -> 0 | X34: =IF(OR(S34=0,S34=""),"-",T34/S34) -> - | Y34: =IF(T34>S34,"SI") -> 0 | AD34: =IF(F34="-","",F34*0.021) | AE34: =IF(S34=0,"-",IF(S34<AD34,(S34/100),((S34-AD34)/100))) -> #VALUE! | AF34: =G34 -> 0 | AG34: =SUM(H34:Q34) -> 0
C35: TOTAL BOTAS | F35: =SUM(F5:F34) -> 844 | G35: =SUM(G5:G34) -> 0 | H35: =SUM(H5:H34) -> 0 | I35: =SUM(I5:I34) -> 0 | J35: =SUM(J5:J34) -> 0 | K35: =SUM(K5:K34) -> 0 | L35: =SUM(L5:L34) -> 0 | M35: =SUM(M5:M34) -> 0 | ... Q35: =SUM(Q5:Q34) -> 0 | R35: =COUNTIF((R5:R34),"Si") -> 7 | S35: =IF(F35="-","",SUM(G35:Q35)) -> 0 | T35: =SUM(T5:T34) -> 0 | V35: =IFERROR(VLOOKUP(U35,'Plantilla y Concentrado'!$B$4:$C$811,2,0),"") | W35: =AVERAGE(W5:W34) -> 0.6 | X35: =IF(OR(S35=0,S35=""),"-",T35/S35) -> - | Y35: =IF(T35>S35,"SI") -> 0 | AD35: =IF(F35="-","",F35*0.021) -> 17.724 | AE35: =IF(S35=0,"-",IF(S35<AD35,(S35/100),((S35-AD35)/100))) -> - | AF35: =G35 -> 0 | AG35: =SUM(H35:Q35) -> 0
C36: B | D36: Caballeros | E36: 48 | F36: 66 | G36: 0 | H36: 0 | I36: 0 | J36: 0 | K36: 0 | L36: 0 | M36: 0 | N36: 0 | O36: 0 | P36: 0 | Q36: 0 | R36: SI | S36: =IF(F36="-","",SUM(G36:Q36)) -> 0 | T36: 0 | U36: 139272 | V36: =IFERROR(VLOOKUP(U36,'Plantilla y Concentrado'!$B$4:$C$811,2,0),"") -> Guzman Navarrete Arlen Esmeralda | W36: =IF(S36=0,1,IF(S36>AD36,(1-AE36),IF(S36<AD36,1))) -> 1 | X36: =IF(OR(S36=0,S36=""),"-",T36/S36) -> - | Y36: =IF(T36>S36,"SI") -> 0 | AD36: =IF(F36="-","",F36*0.021) -> 1.386 | AE36: =IF(S36=0,"-",IF(S36<AD36,(S36/100),((S36-AD36)/100))) -> - | AF36: =G36 -> 0 | AG36: =SUM(H36:Q36) -> 0
C37: B | D37: Caballeros | E37: 49 | F37: 62 | G37: 0 | H37: 0 | I37: 0 | J37: 0 | K37: 0 | L37: 0 | M37: 0 | N37: 0 | O37: 0 | P37: 0 | Q37: 0 | R37: SI | S37: =IF(F37="-","",SUM(G37:Q37)) -> 0 | T37: 0 | U37: 139272 | V37: =IFERROR(VLOOKUP(U37,'Plantilla y Concentrado'!$B$4:$C$811,2,0),"") -> Guzman Navarrete Arlen Esmeralda | W37: =IF(S37=0,1,IF(S37>AD37,(1-AE37),IF(S37<AD37,1))) -> 1 | X37: =IF(OR(S37=0,S37=""),"-",T37/S37) -> - | Y37: =IF(T37>S37,"SI") -> 0 | AD37: =IF(F37="-","",F37*0.021) -> 1.302 | AE37: =IF(S37=0,"-",IF(S37<AD37,(S37/100),((S37-AD37)/100))) -> - | AF37: =G37 -> 0 | AG37: =SUM(H37:Q37) -> 0
C38: B | D38: Caballeros | E38: 50 | F38: 74 | G38: 0 | H38: 0 | I38: 0 | J38: 0 | K38: 0 | L38: 0 | M38: 0 | N38: 0 | O38: 0 | P38: 0 | Q38: 0 | R38: SI | S38: =IF(F38="-","",SUM(G38:Q38)) -> 0 | T38: 0 | U38: 145279 | V38: =IFERROR(VLOOKUP(U38,'Plantilla y Concentrado'!$B$4:$C$811,2,0),"") -> Ferrusca Solis Karla Marcela | W38: =IF(S38=0,1,IF(S38>AD38,(1-AE38),IF(S38<AD38,1))) -> 1 | X38: =IF(OR(S38=0,S38=""),"-",T38/S38) -> - | Y38: =IF(T38>S38,"SI") -> 0 | AD38: =IF(F38="-","",F38*0.021) -> 1.554 | AE38: =IF(S38=0,"-",IF(S38<AD38,(S38/100),((S38-AD38)/100))) -> - | AF38: =G38 -> 0 | AG38: =SUM(H38:Q38) -> 0
C39: B | D39: Caballeros | E39: 51 | F39: 85 | G39: 0 | H39: 0 | I39: 0 | J39: 0 | K39: 0 | L39: 0 | M39: 0 | N39: 0 | O39: 0 | P39: 0 | Q39: 0 | R39: SI | S39: =IF(F39="-","",SUM(G39:Q39)) -> 0 | T39: 0 | U39: 145279 | V39: =IFERROR(VLOOKUP(U39,'Plantilla y Concentrado'!$B$4:$C$811,2,0),"") -> Ferrusca Solis Karla Marcela | W39: =IF(S39=0,1,IF(S39>AD39,(1-AE39),IF(S39<AD39,1))) -> 1 | X39: =IF(OR(S39=0,S39=""),"-",T39/S39) -> - | Y39: =IF(T39>S39,"SI") -> 0 | AD39: =IF(F39="-","",F39*0.021) -> 1.785 | AE39: =IF(S39=0,"-",IF(S39<AD39,(S39/100),((S39-AD39)/100))) -> - | AF39: =G39 -> 0 | AG39: =SUM(H39:Q39) -> 0
C40: B | D40: Caballeros | E40: 52 | F40: 51 | G40: 0 | H40: 0 | I40: 0 | J40: 0 | K40: 0 | L40: 0 | M40: 0 | N40: 0 | O40: 0 | P40: 0 | Q40: 0 | R40: SI | S40: =IF(F40="-","",SUM(G40:Q40)) -> 0 | T40: 0 | U40: 145279 | V40: =IFERROR(VLOOKUP(U40,'Plantilla y Concentrado'!$B$4:$C$811,2,0),"") -> Ferrusca Solis Karla Marcela | W40: =IF(S40=0,1,IF(S40>AD40,(1-AE40),IF(S40<AD40,1))) -> 1 | X40: =IF(OR(S40=0,S40=""),"-",T40/S40) -> - | Y40: =IF(T40>S40,"SI") -> 0 | AD40: =IF(F40="-","",F40*0.021) -> 1.071 | AE40: =IF(S40=0,"-",IF(S40<AD40,(S40/100),((S40-AD40)/100))) -> - | AF40: =G40 -> 0 | AG40: =SUM(H40:Q40) -> 0
C41: B | D41: Caballeros | E41: 53A | F41: 75 | G41: 0 | H41: 0 | I41: 0 | J41: 0 | K41: 0 | L41: 0 | M41: 0 | N41: 0 | O41: 0 | P41: 1 | Q41: 0 | R41: SI | S41: =IF(F41="-","",SUM(G41:Q41)) -> 1 | T41: 1 | U41: 145279 | V41: =IFERROR(VLOOKUP(U41,'Plantilla y Concentrado'!$B$4:$C$811,2,0),"") -> Ferrusca Solis Karla Marcela | W41: =IF(S41=0,1,IF(S41>AD41,(1-AE41),IF(S41<AD41,1))) -> 1 | X41: =IF(OR(S41=0,S41=""),"-",T41/S41) -> 1 | Y41: =IF(T41>S41,"SI") -> 0 | AD41: =IF(F41="-","",F41*0.021) -> 1.575 | AE41: =IF(S41=0,"-",IF(S41<AD41,(S41/100),((S41-AD41)/100))) -> 0.01 | AF41: =G41 -> 0 | AG41: =SUM(H41:Q41) -> 1
C42: B | D42: Caballeros | E42: 56 | F42: 60 | G42: 0 | H42: 0 | I42: 0 | J42: 0 | K42: 0 | L42: 0 | M42: 0 | N42: 0 | O42: 0 | P42: 1 | Q42: 0 | R42: SI | S42: =IF(F42="-","",SUM(G42:Q42)) -> 1 | T42: 1 | U42: 145279 | V42: =IFERROR(VLOOKUP(U42,'Plantilla y Concentrado'!$B$4:$C$811,2,0),"") -> Ferrusca Solis Karla Marcela | W42: =IF(S42=0,1,IF(S42>AD42,(1-AE42),IF(S42<AD42,1))) -> 1 | X42: =IF(OR(S42=0,S42=""),"-",T42/S42) -> 1 | Y42: =IF(T42>S42,"SI") -> 0 | AD42: =IF(F42="-","",F42*0.021) -> 1.26 | AE42: =IF(S42=0,"-",IF(S42<AD42,(S42/100),((S42-AD42)/100))) -> 0.01 | AF42: =G42 -> 0 | AG42: =SUM(H42:Q42) -> 1
C43: B | D43: Caballeros | E43: 57 | F43: 81 | G43: 0 | H43: 0 | I43: 0 | J43: 0 | K43: 0 | L43: 0 | M43: 0 | N43: 1 | O43: 0 | P43: 0 | Q43: 0 | R43: SI | S43: =IF(F43="-","",SUM(G43:Q43)) -> 1 | T43: 1 | U43: 139272 | V43: =IFERROR(VLOOKUP(U43,'Plantilla y Concentrado'!$B$4:$C$811,2,0),"") -> Guzman Navarrete Arlen Esmeralda | W43: =IF(S43=0,1,IF(S43>AD43,(1-AE43),IF(S43<AD43,1))) -> 1 | X43: =IF(OR(S43=0,S43=""),"-",T43/S43) -> 1 | Y43: =IF(T43>S43,"SI") -> 0 | AD43: =IF(F43="-","",F43*0.021) -> 1.701 | AE43: =IF(S43=0,"-",IF(S43<AD43,(S43/100),((S43-AD43)/100))) -> 0.01 | AF43: =G43 -> 0 | AG43: =SUM(H43:Q43) -> 1
C44: B | D44: Caballeros | E44: 58 | F44: 57 | G44: 0 | H44: 0 | I44: 0 | J44: 0 | K44: 0 | L44: 0 | M44: 0 | N44: 0 | O44: 0 | P44: 0 | Q44: 0 | R44: SI | S44: =IF(F44="-","",SUM(G44:Q44)) -> 0 | T44: 0 | U44: 139272 | V44: =IFERROR(VLOOKUP(U44,'Plantilla y Concentrado'!$B$4:$C$811,2,0),"") -> Guzman Navarrete Arlen Esmeralda | W44: =IF(S44=0,1,IF(S44>AD44,(1-AE44),IF(S44<AD44,1))) -> 1 | X44: =IF(OR(S44=0,S44=""),"-",T44/S44) -> - | Y44: =IF(T44>S44,"SI") -> 0 | AD44: =IF(F44="-","",F44*0.021) -> 1.197 | AE44: =IF(S44=0,"-",IF(S44<AD44,(S44/100),((S44-AD44)/100))) -> - | AF44: =G44 -> 0 | AG44: =SUM(H44:Q44) -> 0
...

Sheet Incidencias Colaborador
A1: Incidencias colaborador Calzado | N1: Incidencias colaborador Ropa
A2: Tienda | B2: Catalogo | C2: Nomina | D2: Nombre | F2: INCIDENCIAS OPERATIVAS | N2: Tienda | O2: Catalogo | P2: Nomina | Q2: Nombre | T2: INCIDENCIAS OPERATIVAS
E3: Pasillo | F3: Frenteos | G3: Negados por exhibición | H3: Falta de exhibición | I3: Exhibiciones fuera de politica | J3: # de piezas revueltas | K3: Modelos mal entallados | L3: Total de incidencias | R3: Pasillo | S3: Negados de bodega venta | T3: Negados por exhibición | U3: # de piezas revueltas | V3: Modelos mal entallados | W3: Modelo ordenado y/o acondicionado | X3: Total de incidencias
A4: ='Exhibiciones '!$A$4 -> ECATEPEC | B4: =DBot!$D$4 -> BOTAS | C4: =DBot!AG9 -> 127209 | D4: =IFERROR(VLOOKUP(C4,'Plantilla y Concentrado'!$B$4:$C$677,2,0),"") -> Castillo Ramirez Tania Mayeli | E4: =DBot!A9 -> 1 | F4: =DBot!D9 -> 0 | G4: =DBot!M9 -> 0 | J4: =DBot!U9 -> 0 | K4: =DBot!V9 -> 0 | L4: =SUM(F4:K4) -> 0 | M4: 1 | N4: ='Exhibiciones '!$A$4 -> ECATEPEC | O4: =DMes1!$E$4 -> Ropa Doblada | P4: =DMes1!AC10 -> 144847 | Q4: =DMes1!AD10 -> Islas Magaña Janai | R4: =DMes1!B10 -> Mesa 1 | S4: - | T4: =DMes1!G10 -> 0 | U4: =DMes1!T10 -> 0 | V4: =DMes1!R10 -> 0 | W4: =DMes1!S10 -> 0 | X4: =SUM(S4:W4) -> 0
A5: ='Exhibiciones '!$A$4 -> ECATEPEC | B5: =DBot!$D$4 -> BOTAS | C5: =DBot!AG10 -> 144695 | D5: =IFERROR(VLOOKUP(C5,'Plantilla y Concentrado'!$B$4:$C$677,2,0),"") -> Alvarez Becerra Emiliano | E5: =DBot!A10 -> 2 | F5: =DBot!D10 -> 0 | G5: =DBot!M10 -> 0 | J5: =DBot!U10 -> 0 | K5: =DBot!V10 -> 0 | L5: =SUM(F5:K5) -> 0 | M5: 1 | N5: ='Exhibiciones '!$A$4 -> ECATEPEC | O5: =DMes1!$E$4 -> Ropa Doblada | P5: =DMes1!AC11 -> 144847 | Q5: =DMes1!AD11 -> Islas Magaña Janai | R5: =DMes1!B11 -> Mesa 2 | S5: - | T5: =DMes1!G11 -> 0 | U5: =DMes1!T11 -> 0 | V5: =DMes1!R11 -> 0 | W5: =DMes1!S11 -> 0 | X5: =SUM(S5:W5) -> 0 | Y5: 1
A6: ='Exhibiciones '!$A$4 -> ECATEPEC | B6: =DBot!$D$4 -> BOTAS | C6: =DBot!AG11 -> 144695 | D6: =IFERROR(VLOOKUP(C6,'Plantilla y Concentrado'!$B$4:$C$677,2,0),"") -> Alvarez Becerra Emiliano | E6: =DBot!A11 -> 3 | F6: =DBot!D11 -> 0 | G6: =DBot!M11 -> 0 | J6: =DBot!U11 -> 0 | K6: =DBot!V11 -> 0 | L6: =SUM(F6:K6) -> 0 | M6: 1 | N6: ='Exhibiciones '!$A$4 -> ECATEPEC | O6: =DMes1!$E$4 -> Ropa Doblada | P6: =DMes1!AC12 -> 144847 | Q6: =DMes1!AD12 -> Islas Magaña Janai | R6: =DMes1!B12 -> Mesa 3 | S6: - | T6: =DMes1!G12 -> 0 | U6: =DMes1!T12 -> 0 | V6: =DMes1!R12 -> 0 | W6: =DMes1!S12 -> 0 | X6: =SUM(S6:W6) -> 0 | Y6: 1
A7: ='Exhibiciones '!$A$4 -> ECATEPEC | B7: =DBot!$D$4 -> BOTAS | C7: =DBot!AG12 -> 155938 | D7: =IFERROR(VLOOKUP(C7,'Plantilla y Concentrado'!$B$4:$C$677,2,0),"") -> Aguilar Flores Erika Jazmin | E7: =DBot!A12 -> 15 | F7: =DBot!D12 -> 0 | G7: =DBot!M12 -> 0 | J7: =DBot!U12 -> 0 | K7: =DBot!V12 -> 0 | L7: =SUM(F7:K7) -> 0 | M7: 1 | N7: ='Exhibiciones '!$A$4 -> ECATEPEC | O7: =DMes1!$E$4 -> Ropa Doblada | P7: =DMes1!AC13 -> 147547 | Q7: =DMes1!AD13 -> Rojas Diaz Maria Irene | R7: =DMes1!B13 -> Mesa 4 | S7: - | T7: =DMes1!G13 -> 0 | U7: =DMes1!T13 -> 0 | V7: =DMes1!R13 -> 0 | W7: =DMes1!S13 -> 0 | X7: =SUM(S7:W7) -> 0 | Y7: 1
A8: ='Exhibiciones '!$A$4 -> ECATEPEC | B8: =DBot!$D$4 -> BOTAS | C8: =DBot!AG13 -> 158001 | D8: =IFERROR(VLOOKUP(C8,'Plantilla y Concentrado'!$B$4:$C$677,2,0),"") -> Nuñez Garcia Clarissa Naomi | E8: =DBot!A13 -> 16 | F8: =DBot!D13 -> 0 | G8: =DBot!M13 -> 0 | J8: =DBot!U13 -> 0 | K8: =DBot!V13 -> 0 | L8: =SUM(F8:K8) -> 0 | M8: 1 | N8: ='Exhibiciones '!$A$4 -> ECATEPEC | O8: =DMes1!$E$4 -> Ropa Doblada | P8: =DMes1!AC14 -> 147547 | Q8: =DMes1!AD14 -> Rojas Diaz Maria Irene | R8: =DMes1!B14 -> Mesa 5 | S8: - | T8: =DMes1!G14 -> 0 | U8: =DMes1!T14 -> 0 | V8: =DMes1!R14 -> 0 | W8: =DMes1!S14 -> 0 | X8: =SUM(S8:W8) -> 0 | Y8: 1
A9: ='Exhibiciones '!$A$4 -> ECATEPEC | B9: =DBot!$D$4 -> BOTAS | C9: =DBot!AG14 -> 154648 | D9: =IFERROR(VLOOKUP(C9,'Plantilla y Concentrado'!$B$4:$C$677,2,0),"") -> Sanchez Vazquez Anayareli | E9: =DBot!A14 -> 17 | F9: =DBot!D14 -> 0 | G9: =DBot!M14 -> 0 | J9: =DBot!U14 -> 0 | K9: =DBot!V14 -> 0 | L9: =SUM(F9:K9) -> 0 | M9: 1 | N9: ='Exhibiciones '!$A$4 -> ECATEPEC | O9: =DMes1!$E$4 -> Ropa Doblada | P9: =DMes1!AC15 -> 147547 | Q9: =DMes1!AD15 -> Rojas Diaz Maria Irene | R9: =DMes1!B15 -> Mesa 6 | S9: - | T9: =DMes1!G15 -> 0 | U9: =DMes1!T15 -> 0 | V9: =DMes1!R15 -> 0 | W9: =DMes1!S15 -> 0 | X9: =SUM(S9:W9) -> 0 | Y9: 1
A10: ='Exhibiciones '!$A$4 -> ECATEPEC | B10: =DBot!$D$4 -> BOTAS | C10: =DBot!AG15 -> 144695 | D10: =IFERROR(VLOOKUP(C10,'Plantilla y Concentrado'!$B$4:$C$677,2,0),"") -> Alvarez Becerra Emiliano | E10: =DBot!A15 -> 18 | F10: =DBot!D15 -> 0 | G10: =DBot!M15 -> 0 | J10: =DBot!U15 -> 0 | K10: =DBot!V15 -> 0 | L10: =SUM(F10:K10) -> 0 | M10: 1 | N10: ='Exhibiciones '!$A$4 -> ECATEPEC | O10: =DMes1!$E$4 -> Ropa Doblada | P10: =DMes1!AC16 -> 147547 | Q10: =DMes1!AD16 -> Rojas Diaz Maria Irene | R10: =DMes1!B16 -> Mesa 7 | S10: - | T10: =DMes1!G16 -> 0 | U10: =DMes1!T16 -> 0 | V10: =DMes1!R16 -> 0 | W10: =DMes1!S16 -> 0 | X10: =SUM(S10:W10) -> 0 | Y10: 1
A11: ='Exhibiciones '!$A$4 -> ECATEPEC | B11: =DBot!$D$4 -> BOTAS | C11: =DBot!AG16 -> 136867 | D11: =IFERROR(VLOOKUP(C11,'Plantilla y Concentrado'!$B$4:$C$677,2,0),"") -> Barba Ramirez Jatziri Lizeth | E11: =DBot!A16 -> 19 | F11: =DBot!D16 -> 0 | G11: =DBot!M16 -> 0 | J11: =DBot!U16 -> 0 | K11: =DBot!V16 -> 0 | L11: =SUM(F11:K11) -> 0 | M11: 1 | N11: ='Exhibiciones '!$A$4 -> ECATEPEC | O11: =DMes1!$E$4 -> Ropa Doblada | P11: =DMes1!AC17 -> 158054 | Q11: =DMes1!AD17 -> Hernandez Hernandez Lissete | R11: =DMes1!B17 -> Mesa 8 | S11: - | T11: =DMes1!G17 -> 0 | U11: =DMes1!T17 -> 0 | V11: =DMes1!R17 -> 0 | W11: =DMes1!S17 -> 0 | X11: =SUM(S11:W11) -> 0 | Y11: 1
A12: ='Exhibiciones '!$A$4 -> ECATEPEC | B12: =DBot!$D$4 -> BOTAS | C12: =DBot!AG17 -> 155938 | D12: =IFERROR(VLOOKUP(C12,'Plantilla y Concentrado'!$B$4:$C$677,2,0),"") -> Aguilar Flores Erika Jazmin | E12: =DBot!A17 -> 20 | F12: =DBot!D17 -> 1 | G12: =DBot!M17 -> 0 | J12: =DBot!U17 -> 0 | K12: =DBot!V17 -> 3 | L12: =SUM(F12:K12) -> 4 | M12: 1 | N12: ='Exhibiciones '!$A$4 -> ECATEPEC | O12: =DMes1!$E$4 -> Ropa Doblada | P12: =DMes1!AC18 -> 158054 | Q12: =DMes1!AD18 -> Hernandez Hernandez Lissete | R12: =DMes1!B18 -> Mesa 9 | S12: - | T12: =DMes1!G18 -> 2 | U12: =DMes1!T18 -> 0 | V12: =DMes1!R18 -> 0 | W12: =DMes1!S18 -> 0 | X12: =SUM(S12:W12) -> 2 | Y12: 1
A13: ='Exhibiciones '!$A$4 -> ECATEPEC | B13: =DBot!$D$4 -> BOTAS | C13: =DBot!AG18 -> 154648 | D13: =IFERROR(VLOOKUP(C13,'Plantilla y Concentrado'!$B$4:$C$677,2,0),"") -> Sanchez Vazquez Anayareli | E13: =DBot!A18 -> 21 | F13: =DBot!D18 -> 0 | G13: =DBot!M18 -> 0 | J13: =DBot!U18 -> 0 | K13: =DBot!V18 -> 0 | L13: =SUM(F13:K13) -> 0 | M13: 1 | N13: ='Exhibiciones '!$A$4 -> ECATEPEC | O13: =DMes1!$E$4 -> Ropa Doblada | P13: =DMes1!AC19 -> 158054 | Q13: =DMes1!AD19 -> Hernandez Hernandez Lissete | R13: =DMes1!B19 -> Mesa 10 | S13: - | T13: =DMes1!G19 -> 0 | U13: =DMes1!T19 -> 0 | V13: =DMes1!R19 -> 0 | W13: =DMes1!S19 -> 0 | X13: =SUM(S13:W13) -> 0 | Y13: 1
A14: ='Exhibiciones '!$A$4 -> ECATEPEC | B14: =DBot!$D$4 -> BOTAS | C14: =DBot!AG19 -> 158001 | D14: =IFERROR(VLOOKUP(C14,'Plantilla y Concentrado'!$B$4:$C$677,2,0),"") -> Nuñez Garcia Clarissa Naomi | E14: =DBot!A19 -> 22 | F14: =DBot!D19 -> 0 | G14: =DBot!M19 -> 0 | J14: =DBot!U19 -> 1 | K14: =DBot!V19 -> 0 | L14: =SUM(F14:K14) -> 1 | M14: 1 | N14: ='Exhibiciones '!$A$4 -> ECATEPEC | O14: =DMes1!$E$4 -> Ropa Doblada | P14: =DMes1!AC20 -> 118030 | Q14: =DMes1!AD20 -> Aguilar Bello Martha Maria | R14: =DMes1!B20 -> Mesa 11 | S14: - | T14: =DMes1!G20 -> 0 | U14: =DMes1!T20 -> 0 | V14: =DMes1!R20 -> 0 | W14: =DMes1!S20 -> 0 | X14: =SUM(S14:W14) -> 0 | Y14: 1
A15: ='Exhibiciones '!$A$4 -> ECATEPEC | B15: =DBot!$D$4 -> BOTAS | C15: =DBot!AG20 -> 155938 | D15: =IFERROR(VLOOKUP(C15,'Plantilla y Concentrado'!$B$4:$C$677,2,0),"") -> Aguilar Flores Erika Jazmin | E15: =DBot!A20 -> 23 | F15: =DBot!D20 -> 0 | G15: =DBot!M20 -> 0 | J15: =DBot!U20 -> 0 | K15: =DBot!V20 -> 0 | L15: =SUM(F15:K15) -> 0 | M15: 1 | N15: ='Exhibiciones '!$A$4 -> ECATEPEC | O15: =DMes1!$E$4 -> Ropa Doblada | P15: =DMes1!AC21 -> 118030 | Q15: =DMes1!AD21 -> Aguilar Bello Martha Maria | R15: =DMes1!B21 -> Mesa 12 | S15: - | T15: =DMes1!G21 -> 0 | U15: =DMes1!T21 -> 0 | V15: =DMes1!R21 -> 0 | W15: =DMes1!S21 -> 0 | X15: =SUM(S15:W15) -> 0 | Y15: 1
A16: ='Exhibiciones '!$A$4 -> ECATEPEC | B16: =DBot!$D$4 -> BOTAS | C16: =DBot!AG21 -> 136867 | D16: =IFERROR(VLOOKUP(C16,'Plantilla y Concentrado'!$B$4:$C$677,2,0),"") -> Barba Ramirez Jatziri Lizeth | E16: =DBot!A21 -> 24 | F16: =DBot!D21 -> 0 | G16: =DBot!M21 -> 0 | J16: =DBot!U21 -> 0 | K16: =DBot!V21 -> 0 | L16: =SUM(F16:K16) -> 0 | M16: 1 | N16: ='Exhibiciones '!$A$4 -> ECATEPEC | O16: =DMes1!$E$4 -> Ropa Doblada | P16: =DMes1!AC22 -> 118030 | Q16: =DMes1!AD22 -> Aguilar Bello Martha Maria | R16: =DMes1!B22 -> Mesa 13 | S16: - | T16: =DMes1!G22 -> 0 | U16: =DMes1!T22 -> 0 | V16: =DMes1!R22 -> 0 | W16: =DMes1!S22 -> 0 | X16: =SUM(S16:W16) -> 0 | Y16: 1
... A30: ='Exhibiciones '!$A$4 -> ECATEPEC | B30: =DBot!$D$4 -> BOTAS | C30: =DBot!AG35 -> 0 | D30: =IFERROR(VLOOKUP(C30,'Plantilla y Concentrado'!$B$4:$C$677,2,0),"") | E30: =DBot!A35 -> 0 | F30: =DBot!D35 -> 0 | G30: =DBot!M35 -> 0 | J30: =DBot!U35 -> 0 | K30: =DBot!V35 -> 0 | L30: =SUM(F30:K30) -> 0 | M30: 1 | N30: ='Exhibiciones '!$A$4 -> ECATEPEC | O30: =DMes1!$E$4 -> Ropa Doblada | P30: =DMes1!AC36 -> 149039 | Q30: =DMes1!AD36 -> Californias Almaraz Berenice | R30: =DMes1!B36 -> Mesa 39 | S30: - | T30: =DMes1!G36 -> 0 | U30: =DMes1!T36 -> 0 | V30: =DMes1!R36 -> 0 | W30: =DMes1!S36 -> 0 | X30: =SUM(S30:W30) -> 0 | Y30: 1
A31: ='Exhibiciones '!$A$4 -> ECATEPEC | B31: =DUrb!$E$15 -> 0 | C31: =DUrb!AH20 -> Rosas Paniagua Elizabeth | D31: =IFERROR(VLOOKUP(C31,'Plantilla y Concentrado'!$B$4:$C$677,2,0),"") | E31: =DUrb!B20 -> 800 | F31: =DUrb!E21 -> 0 | G31: =DUrb!N20 -> 0 | J31: =DUrb!V20 -> 5 | K31: =DUrb!W20 -> 0 | L31: =SUM(F31:K31) -> 5 | M31: 1 | N31: ='Exhibiciones '!$A$4 -> ECATEPEC | O31: =DMes1!$E$4 -> Ropa Doblada | P31: =DMes1!AC37 -> 149039 | Q31: =DMes1!AD37 -> Californias Almaraz Berenice | R31: =DMes1!B37 -> Mesa 40 | S31: - | T31: =DMes1!G37 -> 0 | U31: =DMes1!T37 -> 0 | V31: =DMes1!R37 -> 0 | W31: =DMes1!S37 -> 0 | X31: =SUM(S31:W31) -> 0 | Y31: 1
A32: ='Exhibiciones '!$A$4 -> ECATEPEC | B32: =DUrb!$E$15 -> 0 | C32: =DUrb!AH21 -> Lopez Sebastian Karen Jazmin | D32: =IFERROR(VLOOKUP(C32,'Plantilla y Concentrado'!$B$4:$C$677,2,0),"") | E32: =DUrb!B21 -> 367 | F32: =DUrb!E21 -> 0 | G32: =DUrb!N21 -> 0 | J32: =DUrb!V21 -> 0 | K32: =DUrb!W21 -> 0 | L32: =SUM(F32:K32) -> 0 | M32: 1 | N32: ='Exhibiciones '!$A$4 -> ECATEPEC | O32: =DMes1!$E$4 -> Ropa Doblada | P32: =DMes1!AC38 -> 149039 | Q32: =DMes1!AD38 -> Californias Almaraz Berenice | R32: =DMes1!B38 -> Mesa 41 | S32: - | T32: =DMes1!G38 -> 0 | U32: =DMes1!T38 -> 0 | V32: =DMes1!R38 -> 0 | W32: =DMes1!S38 -> 0 | X32: =SUM(S32:W32) -> 0 | Y32: 1
A33: ='Exhibiciones '!$A$4 -> ECATEPEC | B33: =DUrb!$E$15 -> 0 | C33: =DUrb!AH22 | D33: =IFERROR(VLOOKUP(C33,'Plantilla y Concentrado'!$B$4:$C$677,2,0),"") | E33: =DUrb!B22 -> 0 | F33: =DUrb!E22 -> 0 | G33: =DUrb!N22 -> 0 | J33: =DUrb!V22 -> 0 | K33: =DUrb!W22 -> 0 | L33: =SUM(F33:K33) -> 0 | M33: 1 | N33: ='Exhibiciones '!$A$4 -> ECATEPEC | O33: =DMes1!$E$4 -> Ropa Doblada | P33: =DMes1!AC39 -> 149039 | Q33: =DMes1!AD39 -> Californias Almaraz Berenice | R33: =DMes1!B39 -> Mesa 42 | S33: - | T33: =DMes1!G39 -> 0 | U33: =DMes1!T39 -> 0 | V33: =DMes1!R39 -> 0 | W33: =DMes1!S39 -> 0 | X33: =SUM(S33:W33) -> 0 | Y33: 1
A34: ='Exhibiciones '!$A$4 -> ECATEPEC | B34: =DUrb!$E$15 -> 0 | C34: =DUrb!AH23 | D34: =IFERROR(VLOOKUP(C34,'Plantilla y Concentrado'!$B$4:$C$677,2,0),"") | E34: =DUrb!B23 -> 0 | F34: =DUrb!E23 -> 0 | G34: =DUrb!N23 -> 0 | J34: =DUrb!V23 -> 0 | K34: =DUrb!W23 -> 0 | L34: =SUM(F34:K34) -> 0 | M34: 1 | N34: ='Exhibiciones '!$A$4 -> ECATEPEC | O34: =DMes1!$E$4 -> Ropa Doblada | P34: =DMes1!AC40 -> 149039 | Q34: =DMes1!AD40 -> Californias Almaraz Berenice | R34: =DMes1!B40 -> Mesa 43 | S34: - | T34: =DMes1!G40 -> 0 | U34: =DMes1!T40 -> 0 | V34: =DMes1!R40 -> 0 | W34: =DMes1!S40 -> 0 | X34: =SUM(S34:W34) -> 0 | Y34: 1
A35: ='Exhibiciones '!$A$4 -> ECATEPEC | B35: =DUrb!$E$15 -> 0 | C35: =DUrb!AH24 | D35: =IFERROR(VLOOKUP(C35,'Plantilla y Concentrado'!$B$4:$C$677,2,0),"") | E35: =DUrb!B24 -> 0 | F35: =DUrb!E24 -> 0 | G35: =DUrb!N24 -> 0 | J35: =DUrb!V24 -> 0 | K35: =DUrb!W24 -> 0 | L35: =SUM(F35:K35) -> 0 | M35: 1 | N35: ='Exhibiciones '!$A$4 -> ECATEPEC | O35: =DMes1!$E$4 -> Ropa Doblada | P35: =DMes1!AC41 -> 34379 | Q35: =DMes1!AD41 -> Gamboa Soto Concepcion del Carmen | R35: =DMes1!B41 -> Mesa 44 | S35: - | T35: =DMes1!G41 -> 1 | U35: =DMes1!T41 -> 0 | V35: =DMes1!R41 -> 0 | W35: =DMes1!S41 -> 0 | X35: =SUM(S35:W35) -> 1 | Y35: 1
A36: ='Exhibiciones '!$A$4 -> ECATEPEC | B36: =DUrb!$E$15 -> 0 | C36: =DUrb!AH25 | D36: =IFERROR(VLOOKUP(C36,'Plantilla y Concentrado'!$B$4:$C$677,2,0),"") | E36: =DUrb!B25 -> 0 | F36: =DUrb!E25 -> 0 | G36: =DUrb!N25 -> 0 | J36: =DUrb!V25 -> 0 | K36: =DUrb!W25 -> 0 | L36: =SUM(F36:K36) -> 0 | M36: 1 | N36: ='Exhibiciones '!$A$4 -> ECATEPEC | O36: =DMes1!$E$4 -> Ropa Doblada | P36: =DMes1!AC42 -> 34379 | Q36: =DMes1!AD42 -> Gamboa Soto Concepcion del Carmen | R36: =DMes1!B42 -> Mesa 45 | S36: - | T36: =DMes1!G42 -> 0 | U36: =DMes1!T42 -> 0 | V36: =DMes1!R42 -> 0 | W36: =DMes1!S42 -> 0 | X36: =SUM(S36:W36) -> 0 | Y36: 1
A37: ='Exhibiciones '!$A$4 -> ECATEPEC | B37: =DUrb!$E$15 -> 0 | C37: =DUrb!AH26 | D37: =IFERROR(VLOOKUP(C37,'Plantilla y Concentrado'!$B$4:$C$677,2,0),"") | E37: =DUrb!B26 -> 0 | F37: =DUrb!E26 -> 0 | G37: =DUrb!N26 -> 0 | J37: =DUrb!V26 -> 0 | K37: =DUrb!W26 -> 0 | L37: =SUM(F37:K37) -> 0 | M37: 1 | N37: ='Exhibiciones '!$A$4 -> ECATEPEC | O37: =DMes1!$E$4 -> Ropa Doblada | P37: =DMes1!AC43 -> 34379 | Q37: =DMes1!AD43 -> Gamboa Soto Concepcion del Carmen | R37: =DMes1!B43 -> Mesa 46 | S37: - | T37: =DMes1!G43 -> 0 | U37: =DMes1!T43 -> 0 | V37: =DMes1!R43 -> 0 | W37: =DMes1!S43 -> 0 | X37: =SUM(S37:W37) -> 0 | Y37: 1
A38: ='Exhibiciones '!$A$4 -> ECATEPEC | B38: =DUrb!$E$15 -> 0 | C38: =DUrb!AH27 | D38: =IFERROR(VLOOKUP(C38,'Plantilla y Concentrado'!$B$4:$C$677,2,0),"") | E38: =DUrb!B27 -> 0 | F38: =DUrb!E27 -> 0 | G38: =DUrb!N27 -> 0 | J38: =DUrb!V27 -> 0 | K38: =DUrb!W27 -> 0 | L38: =SUM(F38:K38) -> 0 | M38: 1 | N38: ='Exhibiciones '!$A$4 -> ECATEPEC | O38: =DMes1!$E$4 -> Ropa Doblada | P38: =DMes1!AC44 -> 34379 | Q38: =DMes1!AD44 -> Gamboa Soto Concepcion del Carmen | R38: =DMes1!B44 -> Mesa 47 | S38: - | T38: =DMes1!G44 -> 0 | U38: =DMes1!T44 -> 0 | V38: =DMes1!R44 -> 0 | W38: =DMes1!S44 -> 0 | X38: =SUM(S38:W38) -> 0 | Y38: 1
A39: ='Exhibiciones '!$A$4 -> ECATEPEC | B39: =DUrb!$E$15 -> 0 | C39: =DUrb!AH28 | D39: =IFERROR(VLOOKUP(C39,'Plantilla y Concentrado'!$B$4:$C$677,2,0),"") | E39: =DUrb!B28 -> 0 | F39: =DUrb!E28 -> 0 | G39: =DUrb!N28 -> 0 | J39: =DUrb!V28 -> 0 | K39: =DUrb!W28 -> 0 | L39: =SUM(F39:K39) -> 0 | M39: 1 | N39: ='Exhibiciones '!$A$4 -> ECATEPEC | O39: =DMes1!$E$4 -> Ropa Doblada | P39: =DMes1!AC45 -> 34379 | Q39: =DMes1!AD45 -> Gamboa Soto Concepcion del Carmen | R39: =DMes1!B45 -> Mesa 48 | S39: - | T39: =DMes1!G45 -> 0 | U39: =DMes1!T45 -> 0 | V39: =DMes1!R45 -> 0 | W39: =DMes1!S45 -> 0 | X39: =SUM(S39:W39) -> 0 | Y39: 1
A40: ='Exhibiciones '!$A$4 -> ECATEPEC | B40: =DUrb!$E$15 -> 0 | C40: =DUrb!AH29 | D40: =IFERROR(VLOOKUP(C40,'Plantilla y Concentrado'!$B$4:$C$677,2,0),"") | E40: =DUrb!B29 -> 0 | F40: =DUrb!E29 -> 0 | G40: =DUrb!N29 -> 0 | J40: =DUrb!V29 -> 0 | K40: =DUrb!W29 -> 0 | L40: =SUM(F40:K40) -> 0 | M40: 1 | N40: ='Exhibiciones '!$A$4 -> ECATEPEC | O40: =DMes1!$E$4 -> Ropa Doblada | P40: =DMes1!AC46 -> 151655 | Q40: =DMes1!AD46 -> Mireles Saucedo Fabiola Alehandra | R40: =DMes1!B46 -> Mesa 49 | S40: - | T40: =DMes1!G46 -> 0 | U40: =DMes1!T46 -> 0 | V40: =DMes1!R46 -> 0 | W40: =DMes1!S46 -> 0 | X40: =SUM(S40:W40) -> 0 | Y40: 1
A41: ='Exhibiciones '!$A$4 -> ECATEPEC | B41: =DUrb!$E$15 -> 0 | C41: =DUrb!AH30 -> 0 | D41: =IFERROR(VLOOKUP(C41,'Plantilla y Concentrado'!$B$4:$C$677,2,0),"") | E41: =DUrb!B30 -> 8864 | F41: =DUrb!E30 -> 0 | G41: =DUrb!N30 -> 0 | J41: =DUrb!V30 -> 9 | K41: =DUrb!W30 -> 0 | L41: =SUM(F41:K41) -> 9 | M41: 1 | N41: ='Exhibiciones '!$A$4 -> ECATEPEC | O41: =DMes1!$E$4 -> Ropa Doblada | P41: =DMes1!AC47 -> 151655 | Q41: =DMes1!AD47 -> Mireles Saucedo Fabiola Alehandra | R41: =DMes1!B47 -> Mesa 50 | S41: - | T41: =DMes1!G47 -> 0 | U41: =DMes1!T47 -> 0 | V41: =DMes1!R47 -> 0 | W41: =DMes1!S47 -> 0 | X41: =SUM(S41:W41) -> 0 | Y41: 1
A42: ='Exhibiciones '!$A$4 -> ECATEPEC | B42: =DUrb!$E$15 -> 0 | C42: =DUrb!AH31 -> 0 | D42: =IFERROR(VLOOKUP(C42,'Plantilla y Concentrado'!$B$4:$C$677,2,0),"") | E42: =DUrb!B31 -> 0 | F42: =DUrb!E31 -> 0 | G42: =DUrb!N31 -> 0 | J42: =DUrb!V31 -> 0 | K42: =DUrb!W31 -> 0 | L42: =SUM(F42:K42) -> 0 | M42: 1 | N42: ='Exhibiciones '!$A$4 -> ECATEPEC | O42: =DMes1!$E$4 -> Ropa Doblada | P42: =DMes1!AC48 -> 151655 | Q42: =DMes1!AD48 -> Mireles Saucedo Fabiola Alehandra | R42: =DMes1!B48 -> Mesa 51 | S42: - | T42: =DMes1!G48 -> 0 | U42: =DMes1!T48 -> 0 | V42: =DMes1!R48 -> 0 | W42: =DMes1!S48 -> 0 | X42: =SUM(S42:W42) -> 0 | Y42: 1
A43: ='Exhibiciones '!$A$4 -> ECATEPEC | B43: =DUrb!$E$15 -> 0 | C43: =DUrb!AH32 -> 0 | D43: =IFERROR(VLOOKUP(C43,'Plantilla y Concentrado'!$B$4:$C$677,2,0),"") | E43: =DUrb!B32 -> 0 | F43: =DUrb!E32 -> 0 | G43: =DUrb!N32 -> 0 | J43: =DUrb!V32 -> 0 | K43: =DUrb!W32 -> 0 | L43: =SUM(F43:K43) -> 0 | M43: 1 | N43: ='Exhibiciones '!$A$4 -> ECATEPEC | O43: =DMes1!$E$4 -> Ropa Doblada | P43: =DMes1!AC49 -> 0 | Q43: =DMes1!AD49 | R43: =DMes1!B49 -> 0 | S43: - | T43: =DMes1!G49 -> 0 | U43: =DMes1!T49 -> 0 | V43: =DMes1!R49 -> 0 | W43: =DMes1!S49 -> 0 | X43: =SUM(S43:W43) -> 0 | Y43: 1
... A51: ='Exhibiciones '!$A$4 -> ECATEPEC | B51: =DUrb!$E$15 -> 0 | C51: =DUrb!AH40 -> 0 | D51: =IFERROR(VLOOKUP(C51,'Plantilla y Concentrado'!$B$4:$C$677,2,0),"") | E51: =DUrb!B40 -> 0 | F51: =DUrb!E40 -> 0 | G51: =DUrb!N40 -> 0 | J51: =DUrb!V40 -> 0 | K51: =DUrb!W40 -> 0 | L51: =SUM(F51:K51) -> 0 | M51: 1 | N51: ='Exhibiciones '!$A$4 -> ECATEPEC | O51: =DMes1!$E$4 -> Ropa Doblada | P51: =DMes1!AC57 -> 0 | Q51: =DMes1!AD57 | R51: =DMes1!B57 -> 0 | S51: - | T51: =DMes1!G57 -> 0 | U51: =DMes1!T57 -> 0 | V51: =DMes1!R57 -> 0 | W51: =DMes1!S57 -> 0 | X51: =SUM(S51:W51) -> 0 | Y51: 1
A52: ='Exhibiciones '!$A$4 -> ECATEPEC | B52: =DEsc!$D$4 -> Escolar | C52: =DEsc!AG9 -> 127209 | D52: =IFERROR(VLOOKUP(C52,'Plantilla y Concentrado'!$B$4:$C$677,2,0),"") -> Castillo Ramirez Tania Mayeli | E52: =DEsc!A9 -> 41A | F52: =DEsc!D9 -> 0 | G52: =DEsc!M9 -> 0 | J52: =DEsc!U9 -> 1 | K52: =DEsc!V9 -> 0 | L52: =SUM(F52:K52) -> 1 | M52: 1 | N52: ='Exhibiciones '!$A$4 -> ECATEPEC | O52: =DMes1!$E$4 -> Ropa Doblada | P52: =DMes1!AC58 -> 0 | Q52: =DMes1!AD58 | R52: =DMes1!B58 -> 0 | S52: - | T52: =DMes1!G58 -> 0 | U52: =DMes1!T58 -> 0 | V52: =DMes1!R58 -> 0 | W52: =DMes1!S58 -> 0 | X52: =SUM(S52:W52) -> 0 | Y52: 1
A53: ='Exhibiciones '!$A$4 -> ECATEPEC | B53: =DEsc!$D$4 -> Escolar | C53: =DEsc!AG10 -> 136675 | D53: =IFERROR(VLOOKUP(C53,'Plantilla y Concentrado'!$B$4:$C$677,2,0),"") -> Montiel Ramirez Cintya Elizabeth | E53: =DEsc!A10 -> 42 | F53: =DEsc!D10 -> 0 | G53: =DEsc!M10 -> 0 | J53: =DEsc!U10 -> 0 | K53: =DEsc!V10 -> 0 | L53: =SUM(F53:K53) -> 0 | M53: 1 | N53: ='Exhibiciones '!$A$4 -> ECATEPEC | O53: =DMes1!$E$4 -> Ropa Doblada | P53: =DMes1!AC59 -> 0 | Q53: =DMes1!AD59 | R53: =DMes1!B59 -> 0 | S53: - | T53: =DMes1!G59 -> 0 | U53: =DMes1!T59 -> 0 | V53: =DMes1!R59 -> 0 | W53: =DMes1!S59 -> 0 | X53: =SUM(S53:W53) -> 0 | Y53: 1
A54: ='Exhibiciones '!$A$4 -> ECATEPEC | B54: =DEsc!$D$4 -> Escolar | C54: =DEsc!AG11 -> 151630 | D54: =IFERROR(VLOOKUP(C54,'Plantilla y Concentrado'!$B$4:$C$677,2,0),"") -> Muñoz Lara Karla Paola | E54: =DEsc!A11 -> 43 | F54: =DEsc!D11 -> 0 | G54: =DEsc!M11 -> 0 | J54: =DEsc!U11 -> 1 | K54: =DEsc!V11 -> 0 | L54: =SUM(F54:K54) -> 1 | M54: 1 | N54: ='Exhibiciones '!$A$4 -> ECATEPEC | O54: =DMes1!$E$4 -> Ropa Doblada | P54: =DMes1!AC60 -> 0 | Q54: =DMes1!AD60 | R54: =DMes1!B60 -> 0 | S54: - | T54: =DMes1!G60 -> 0 | U54: =DMes1!T60 -> 0 | V54: =DMes1!R60 -> 0 | W54: =DMes1!S60 -> 0 | X54: =SUM(S54:W54) -> 0 | Y54: 1
A55: ='Exhibiciones '!$A$4 -> ECATEPEC | B55: =DEsc!$D$4 -> Escolar | C55: =DEsc!AG12 -> 154648 | D55: =IFERROR(VLOOKUP(C55,'Plantilla y Concentrado'!$B$4:$C$677,2,0),"") -> Sanchez Vazquez Anayareli | E55: =DEsc!A12 -> 44 | F55: =DEsc!D12 -> 0 | G55: =DEsc!M12 -> 0 | J55: =DEsc!U12 -> 0 | K55: =DEsc!V12 -> 0 | L55: =SUM(F55:K55) -> 0 | M55: 1 | N55: ='Exhibiciones '!$A$4 -> ECATEPEC | O55: =DMes1!$E$4 -> Ropa Doblada | P55: =DMes1!AC61 -> 0 | Q55: =DMes1!AD61 | R55: =DMes1!B61 -> 0 | S55: - | T55: =DMes1!G61 -> 0 | U55: =DMes1!T61 -> 0 | V55: =DMes1!R61 -> 0 | W55: =DMes1!S61 -> 0 | X55: =SUM(S55:W55) -> 0 | Y55: 1
A56: ='Exhibiciones '!$A$4 -> ECATEPEC | B56: =DEsc!$D$4 -> Escolar | C56: =DEsc!AG13 -> 136675 | D56: =IFERROR(VLOOKUP(C56,'Plantilla y Concentrado'!$B$4:$C$677,2,0),"") -> Montiel Ramirez Cintya Elizabeth | E56: =DEsc!A13 -> 45 | F56: =DEsc!D13 -> 0 | G56: =DEsc!M13 -> 0 | J56: =DEsc!U13 -> 0 | K56: =DEsc!V13 -> 0 | L56: =SUM(F56:K56) -> 0 | M56: 1 | N56: ='Exhibiciones '!$A$4 -> ECATEPEC | O56: =DMes1!$E$4 -> Ropa Doblada | P56: =DMes1!AC62 -> 0 | Q56: =DMes1!AD62 | R56: =DMes1!B62 -> 0 | S56: - | T56: =DMes1!G62 -> 0 | U56: =DMes1!T62 -> 0 | V56: =DMes1!R62 -> 0 | W56: =DMes1!S62 -> 0 | X56: =SUM(S56:W56) -> 0 | Y56: 1
A57: ='Exhibiciones '!$A$4 -> ECATEPEC | B57: =DEsc!$D$4 -> Escolar | C57: =DEsc!AG14 -> 155938 | D57: =IFERROR(VLOOKUP(C57,'Plantilla y Concentrado'!$B$4:$C$677,2,0),"") -> Aguilar Flores Erika Jazmin | E57: =DEsc!A14 -> 46 | F57: =DEsc!D14 -> 0 | G57: =DEsc!M14 -> 0 | J57: =DEsc!U14 -> 0 | K57: =DEsc!V14 -> 0 | L57: =SUM(F57:K57) -> 0 | M57: 1 | N57: ='Exhibiciones '!$A$4 -> ECATEPEC | O57: =DMes1!$E$4 -> Ropa Doblada | P57: =DMes1!AC63 -> 0 | Q57: =DMes1!AD63 | R57: =DMes1!B63 -> 0 | S57: - | T57: =DMes1!G63 -> 0 | U57: =DMes1!T63 -> 0 | V57: =DMes1!R63 -> 0 | W57: =DMes1!S63 -> 0 | X57: =SUM(S57:W57) -> 0 | Y57: 1
A58: ='Exhibiciones '!$A$4 -> ECATEPEC | B58: =DEsc!$D$4 -> Escolar | C58: =DEsc!AG15 -> 154648 | D58: =IFERROR(VLOOKUP(C58,'Plantilla y Concentrado'!$B$4:$C$677,2,0),"") -> Sanchez Vazquez Anayareli | E58: =DEsc!A15 -> 47B | F58: =DEsc!D15 -> 0 | G58: =DEsc!M15 -> 0 | J58: =DEsc!U15 -> 0 | K58: =DEsc!V15 -> 0 | L58: =SUM(F58:K58) -> 0 | M58: 1 | N58: ='Exhibiciones '!$A$4 -> ECATEPEC | O58: =DMes1!$E$4 -> Ropa Doblada | P58: =DMes1!AC64 -> 0 | Q58: =DMes1!AD64 | R58: =DMes1!B64 -> 0 | S58: - | T58: =DMes1!G64 -> 0 | U58: =DMes1!T64 -> 0 | V58: =DMes1!R64 -> 0 | W58: =DMes1!S64 -> 0 | X58: =SUM(S58:W58) -> 0 | Y58: 1
A59: ='Exhibiciones '!$A$4 -> ECATEPEC | B59: =DEsc!$D$4 -> Escolar | C59: =DEsc!AG19 -> 0 | D59: =IFERROR(VLOOKUP(C59,'Plantilla y Concentrado'!$B$4:$C$677,2,0),"") | E59: =DEsc!A19 -> 0 | F59: =DEsc!D19 -> 0 | G59: =DEsc!M19 -> 0 | J59: =DEsc!U19 -> 0 | K59: =DEsc!V19 -> 0 | L59: =SUM(F59:K59) -> 0 | M59: 1 | N59: ='Exhibiciones '!$A$4 -> ECATEPEC | O59: ='DColg1 '!$D$4 -> Ropa Colgada | P59: ='DColg1 '!AB9 -> 122694 | Q59: ='DColg1 '!AC9 -> Garcia Jimenez Maria Elena | R59: ='DColg1 '!A9 -> R. COLGADA 01 | S59: ='DColg1 '!D9 -> 0 | T59: ='DColg1 '!H9 -> 0 | U59: ='DColg1 '!R9 -> 0 | V59: ='DColg1 '!S9 -> 0 | W59: ='DColg1 '!T9 -> 0 | X59: =SUM(S59:W59) -> 0 | Y59: 1
A60: ='Exhibiciones '!$A$4 -> ECATEPEC | B60: =DEsc!$D$4 -> Escolar | C60: =DEsc!AG17 -> 0 | D60: =IFERROR(VLOOKUP(C60,'Plantilla y Concentrado'!$B$4:$C$677,2,0),"") | E60: =DEsc!A17 -> 0 | F60: =DEsc!D17 -> 0 | G60: =DEsc!M17 -> 0 | J60: =DEsc!U17 -> 0 | K60: =DEsc!V17 -> 0 | L60: =SUM(F60:K60) -> 0 | M60: 1 | N60: ='Exhibiciones '!$A$4 -> ECATEPEC | O60: ='DColg1 '!$D$4 -> Ropa Colgada | P60: ='DColg1 '!AB10 -> 122694 | Q60: ='DColg1 '!AC10 -> Garcia Jimenez Maria Elena | R60: ='DColg1 '!A10 -> R. COLGADA 02 | S60: ='DColg1 '!D10 -> 0 | T60: ='DColg1 '!H10 -> 1 | U60: ='DColg1 '!R10 -> 0 | V60: ='DColg1 '!S10 -> 0 | W60: ='DColg1 '!T10 -> 0 | X60: =SUM(S60:W60) -> 1 | Y60: 1
...

Sheet Plantilla y Concentrado
A4: 09.02.2026 | M4: 1
B5: 66 | C5: Gomez Cardenas Laura Minerva | D5: Estado de México | E5: Tienda Ecatepec | F5: Administrativo Quin | G5: PST002G501 | H5: Recursos Humanos | I5: 30000004 | J5: Analista | K5: Dir Capital Humano
B6: 194 | C6: Arellano Arellano Cyntia Elizabeth | D6: Estado de México | E6: Tienda Ecatepec | F6: Operativo Quin | G6: PST002G301 | H6: Gerencia Servicios | I6: 30000069 | J6: Supervisor | K6: Gerencia General
B7: 233 | C7: Vidaurri Morales Yareni | D7: Estado de México | E7: Tienda Ecatepec | F7: Operativo Quin | G7: PST002G181 | H7: Golden | I7: 30000069 | J7: Supervisor | K7: Comercial
B8: 240 | C8: Hernandez Gonzalez Anita | D8: Estado de México | E8: Tienda Ecatepec | F8: Operativo Quin | G8: PST002G404 | H8: Verific Garantías | I8: 30000074 | J8: Verificador | K8: Operaciones
B9: 376 | C9: Fernandez Galeana Rafael | D9: Estado de México | E9: Tienda Ecatepec | F9: Gerencia | G9: PST002G001 | H9: Gerencia General | I9: 30000036 | J9: Gerente | K9: Dir Comercial Operativa
B10: 483 | C10: Alvarado Hernandez Irma | D10: Estado de México | E10: Tienda Ecatepec | F10: Operativo Quin | G10: PST002G309 | H10: Cambios y Devolucion | I10: 30000074 | J10: Verificador | K10: Operaciones
B11: 646 | C11: Hernandez Gonzalez Israel | D11: Estado de México | E11: Tienda Ecatepec | F11: Operativo Sem | G11: PST002G204 | H11: Etiquetado | I11: 30000009 | J11: Auxiliar | K11: Operaciones
B12: 758 | C12: Lopez Martinez Jannet | D12: Estado de México | E12: Tienda Ecatepec | F12: Administrativo Quin | G12: PST002G021 | H12: Caja General | I12: 30000043 | J12: Jefe | K12: Tesoreria
B13: 937 | C13: Garcia Moreno Enrique | D13: Estado de México | E13: Tienda Ecatepec | F13: Operativo Sem | G13: PST002G206 | H13: Bodegas | I13: 30000009 | J13: Auxiliar | K13: Operaciones
B14: 971 | C14: Cordova Ramirez Elizabeth Edith | D14: Estado de México | E14: Tienda Ecatepec | F14: Gerencia | G14: PST002G118 | H14: Producto | I14: 30000036 | J14: Gerente | K14: Gerencia General
B15: 998 | C15: Vargas Guadalupe Maria de Jesus Alicia | D15: Estado de México | E15: Tienda Ecatepec | F15: Operativo Sem | G15: PST002G160 | H15: Ropa | I15: 30000006 | J15: Asesor | K15: Comercial
B16: 1183 | C16: Muñoz Sanchez Yesmet Wendy | D16: Estado de México | E16: Tienda Ecatepec | F16: Operativo Sem | G16: PST002G192 | H16: Cambios Piso | I16: 30000009 | J16: Auxiliar | K16: Operaciones
... B438: 158262 | C438: Sanchez Toledo Fatima Azul | D438: Estado de México | E438: Tienda Ecatepec | F438: Operativo Sem | G438: PST073G000 | H438: Outlet Ecatepec | I438: 30000006 | J438: Asesor | K438: Outlet Comercial

Sheet Bot
D1: Formato para el registro del Check list del Supervisor | I1: Código: MS-CLS/01-18
I2: Versión: 001
I3: Vigencia a partir : Mayo 2022
B4: Tienda | D4: Ecatepec
B5: Fecha de auditoria: | D5: 30/Junio/2026 | E5: Gerente Comercial | F5: Luis ALberto Pérez
B6: Catálogo: | D6: BOTAS | E6: Gerente Com. Operativo | F6: Alejandro Balleza Gómez | M6: SI
B7: Supervisor de Catalogo | D7: Hazminda Garcia | E7: Gerente de Servicios | M7: NO
B8: # de Nomina | D8: 1752 | E8: Gerente de Operaciones | F8: Alejandro Balleza Gómez | M8: NA
B11: Responsable | C11: Definición de Servicio | D11: Indicador | E11: Criterio de Evaluación | F11: Número | G11: Alcance | H11: Valor | I11: Logro x actividad | J11: Logro x departamento | K11: Que dato se captura? | L11: Como obtengo este dato o cual es el entregable?
B12: Informativo | D12: Total de Tallas del Catálogo | F12: =DBot!B36 -> 5112
B13: Informativo | D13: Total de Tallas auditadas | F13: =DBot!C36 -> 4958 | G13: =IF(F12=0,"",F13/F12) -> 0.9698748
B14: Informativo | D14: Número de pasillos
B15: Informativo | D15: Sugerido del catálogo a 7 días
B16: Resurtido | C16: Producto | D16: Pasillos y piso de venta libre de mercancia por suvir a bodega. ( bodegas en el piso sin quien las trabaje ) | E16: Si cumple "Si" , si no cumple coloca "No" | F16: Na | G16: =IF(F16="NA","",IF(F16="SI",1,0)) | H16: 100 | I16: =IF(G16="","",IF(G16=0,0,IF(G16>0,(H16*G16)))) | J16: =IF(SUM(M16)=0,"-",SUM(I16)/SUM(M16)) -> - | K16: Cumple=100%, No cumple=0% | L16: Recorrido – Auditoría de Check List | M16: =IF(F16="NA","No aplica",H16) -> No aplica
B17: Auxiliar de Zona DEN | C17: Comercial | D17: Zona DEN en orden y con calzado del día (validar la entrega diaria de Lunes a Sábado) | E17: Si se realiza la entrega diaria = "Si", sino = "No" | F17: Na | G17: =IF(F17="NA","",IF(F17="SI",1,0)) | H17: 100 | I17: =IF(G17="","",IF(G17=0,0,IF(G17>0,(H17*G17)))) | J17: =IF(SUM(M17)=0,"-",SUM(I17)/SUM(M17)) -> - | K17: Cumple=100%, No cumple=0% | L17: Zona Den muestra reporte de entrega de mercancía ya sea de Nones o defectos | M17: =IF(F17="NA","No aplica",H17) -> No aplica
B18: Cambios Operativo | C18: Producto | D18: Pasillos y piso de venta libre de cambios. (cambios en el piso sin quien lo ubique = 0) | E18: Si hay cambios en el piso, Valida nombre de la persona destinada para subirlos, si esta la persona coloca "Si" , si no cumple coloca "No" | F18: Na | G18: =IF(F18="NA","",IF(F18="SI",1,0)) | H18: 50 | I18: =IF(G18="","",IF(G18=0,0,IF(G18>0,(H18*G18)))) | J18: =IF(SUM(M18:M19)=0,"-",SUM(I18:I19)/SUM(M18:M19)) -> - | K18: Cumple=100%, No cumple=0% | L18: Recorrido – Auditoría de Check List | M18: =IF(F18="NA","No aplica",H18) -> No aplica
D19: Personal de cambios ubicando el calzado en el modelo correcto | E19: Si hay personal ubicando cambios valida alguno, si los coloca en el modelo correcto, Si cumple "Si" , si no cumple coloca "No" | F19: Na | G19: =IF(F19="NA","",IF(F19="SI",1,0)) | H19: 50 | I19: =IF(G19="","",IF(G19=0,0,IF(G19>0,(H19*G19)))) | K19: Cumple=100%, No cumple=0% | L19: Recorrido – Auditoría de Check List | M19: =IF(F19="NA","No aplica",H19) -> No aplica
B20: Supervisor Calzado | C20: Comercial | D20: Se tiene evidencia de recorrido diario de revisión de exhibiciones | E20: Debe estar documentado el recorrido, si cumple coloca "Si" sino coloca cero "No" | F20: Na | G20: =IF(F20="NA","",IF(F20="SI",1,0)) | H20: 10 | I20: =IF(G20="","",IF(G20=0,0,IF(G20>0,(H20*G20)))) | J20: =IF(SUM(M20:M30)=0,"-",SUM(I20:I30)/SUM(M20:M30)) -> - | K20: Cumple=100%, No cumple=0% | L20: Supervisor de Piso muestra evidencia de recorrido | M20: =IF(F20="NA","No aplica",H20) -> No aplica
D21: # de frenteos encontrados en auditoria | E21: Por cada negado detectado como frenteo detectado en auditoria -5% | F21: Na | G21: =IF(F21="NA","",IF(F21<20,1-(F21*5/100),IF(F21>10,0))) | H21: 12 | I21: =IF(G21="","",IF(G21=0,0,IF(G21>0,(H21*G21)))) | K21: Total de Modelos revueltos | L21: Recorrido – Auditoría de Check List | M21: =IF(F21="NA","No aplica",H21) -> No aplica
D23: # de Pasillos con mercancía desalineada | E23: # pasillos NO alineados / Total de pasillos | F23: Na | G23: =IF(F23="NA","",1-(F23/F14)) | H23: 10 | I23: =IF(G23="","",IF(G23=0,0,IF(G23>0,(H23*G23)))) | K23: Cumple=100%, No cumple=0% | L23: Recorrido – Auditoría de Check List | M23: =IF(F23="NA","No aplica",H23) -> No aplica
D24: Muestra evidencia de la validación de curvas al día (Si se realiza Check List antes de las 12am puede mostrar evidencia del día anterior) | E24: Si cumple "Si" , si no cumple coloca "No" | F24: Na | G24: =IF(F24="NA","",IF(F24="SI",1,0)) | H24: 21 | I24: =IF(G24="","",IF(G24=0,0,IF(G24>0,(H24*G24)))) | K24: Cumple=SI, No cumple=NO | L24: Reporte de Certificacion de curvas | M24: =IF(F24="NA","No aplica",H24) -> No aplica
I25: =IF(G25="","",IF(G25=0,0,IF(G25>0,(H25*G25))))
D26: El colaborador conoce o da opciones de modelos similares de los modelos Agotados en su totalidad | E26: Si cumple "Si" , si no cumple coloca "No" ( Se valida a 2 colaboradores ) | F26: Na | G26: =IF(F26="NA","",IF(F26="SI",1,0)) | H26: 11 | I26: =IF(G26="","",IF(G26=0,0,IF(G26>0,(H26*G26)))) | K26: Cumple=SI, No cumple=NO | L26: Recorrido – Auditoría de Check List | M26: =IF(F26="NA","No aplica",H26) -> No aplica
D27: Colaboradores conocen sus funciones que vienen en su Rutina. | E27: Si cumple "Si" , si no cumple coloca "No" | F27: Na | G27: =IF(F27="NA","",IF(F27="Si",1,0)) | H27: 11 | I27: =IF(G27="","",IF(G27=0,0,IF(G27>0,(H27*G27)))) | K27: Cumple=SI, No cumple=NO | L27: Recorrido – Auditoría de Check List | M27: =IF(F27="NA","No aplica",H27) -> No aplica
D28: Colaboradores conocen sus resultados de su ultima auditoria. | E28: Si cumple "Si" , si no cumple coloca "No" | F28: Na | G28: =IF(F28="NA","",IF(F28="Si",1,0)) | H28: 9 | I28: =IF(G28="","",IF(G28=0,0,IF(G28>0,(H28*G28)))) | K28: Cumple=SI, No cumple=NO | L28: Recorrido – Auditoría de Check List | M28: =IF(F28="NA","No aplica",H28) -> No aplica
D29: El supervisor cuenta con evidencia de que ya entrego su rutina a sus colaboradores | E29: Si cumple "Si" , si no cumple coloca "No" | F29: Na | G29: =IF(F29="NA","",IF(F29="Si",1,0)) | H29: 8 | I29: =IF(G29="","",IF(G29=0,0,IF(G29>0,(H29*G29)))) | K29: Cumple=SI, No cumple=NO | L29: Evidencia de listado de entrega de rutinas | M29: =IF(F29="NA","No aplica",H29) -> No aplica
C30: Producto | D30: Se cuenta con listado de Cajas Maltratadas que entrega a Zona DEN, para ser solicitadas al área de Compras | E30: Si cumple "Si" , si no cumple coloca "No" | F30: Na | G30: =IF(F30="NA","",IF(F30="SI",1,0)) | H30: 8 | I30: =IF(G30="","",IF(G30=0,0,IF(G30>0,(H30*G30)))) | K30: Cumple=SI, No cumple=NO | L30: Listado actualizado de cajas | M30: =IF(F30="NA","No aplica",H30) -> No aplica
B31: Visual Merchandising | C31: Auto conducción | D31: Publicidad en buen estado y vigente | E31: Si cumple "Si" , si no cumple coloca "No" | F31: Na | G31: =IF(F31="NA","",IF(F31="SI",1,0)) | H31: 30 | I31: =IF(G31="","",IF(G31=0,0,IF(G31>0,(H31*G31)))) | J31: =IF(SUM(M31:M33)=0,"-",SUM(I31:I33)/SUM(M31:M33)) -> - | K31: Cumple=SI, No cumple=NO | L31: Recorrido – Auditoría de Check List | M31: =IF(F31="NA","No aplica",H31) -> No aplica
D32: La numeración del pasillo en buenas condiciones | E32: Si cumple "Si" , si no cumple coloca "No" | F32: Na | G32: =IF(F32="NA","",IF(F32="SI",1,0)) | H32: 30 | I32: =IF(G32="","",IF(G32=0,0,IF(G32>0,(H32*G32)))) | K32: Cumple=SI, No cumple=NO | L32: Recorrido – Auditoría de Check List | M32: =IF(F32="NA","No aplica",H32) -> No aplica
D33: Los pendones visibles al socio , en buenas condiciones, alineados y limpios | E33: Si cumple "Si" , si no cumple coloca "No" | F33: Na | G33: =IF(F33="NA","",IF(F33="SI",1,0)) | H33: 40 | I33: =IF(G33="","",IF(G33=0,0,IF(G33>0,(H33*G33)))) | K33: Cumple=SI, No cumple=NO | L33: Recorrido – Auditoría de Check List | M33: =IF(F33="NA","No aplica",H33) -> No aplica
B34: Recibo | C34: Comercial | D34: Se recibió el reporte Hot list (Origen) | E34: Si cumple "Si" , si no cumple coloca "No" | F34: Na | G34: =IF(F34="NA","",IF(F34="SI",1,0)) | H34: 100 | I34: =IF(G34="","",IF(G34=0,0,IF(G34>0,(H34*G34)))) | J34: =IF(SUM(M34)=0,"-",SUM(I34)/SUM(M34)) -> - | K34: Cumple=SI, No cumple=NO | L34: Reporte de Origen actualizado | M34: =IF(F34="NA","No aplica",H34) -> No aplica
B35: Sistemas | C35: Auto conducción | D35: Revisión de kioscos encendidos y limpios funcion | E35: Si cumple "Si" , si no cumple coloca "No" | F35: Na | G35: =IF(F35="NA","",IF(F35="SI",1,0)) | H35: 100 | I35: =IF(G35="","",IF(G35=0,0,IF(G35>0,(H35*G35)))) | J35: =IF(SUM(M35)=0,"-",SUM(I35)/SUM(M35)) -> - | K35: Recorrido – Auditoría de Check List | L35: Recorrido – Auditoría de Check List | M35: =IF(F35="NA","No aplica",H35) -> No aplica
B36: Indicadores | C36: Comercial | D36: % del check list de cabeceras de catalogo | E36: % de calificación que se obtuvo el la revision de las cabeceras en base a las fichas de instruccion | F36: Na | G36: =IF(F36="Na","",F36) | H36: 50 | I36: =IF(G36="","",IF(G36=0,0,IF(G36>0,(H36*G36)))) | J36: =IF(SUM(M36:M38)=0,"-",SUM(I36:I38)/SUM(M36:M38)) -> - | K36: Recorrido – Auditoría de Check List | L36: Recorrido – Auditoría de Check List | M36: =IF(F36="NA","No aplica",H36) -> No aplica
D37: % de check list de supervisor de calzado | E37: % de calificación de check list de supervisor, (Semana Anterior o ultima auditoria) | F37: Na | G37: =IF(F37="Na","",F37) | H37: 50 | I37: =IF(G37="","",IF(G37=0,0,IF(G37>0,(H37*G37)))) | K37: Recorrido – Auditoría de Check List | L37: Recorrido – Auditoría de Check List | M37: =IF(F37="NA","No aplica",H37) -> No aplica
E40: =D6 -> BOTAS
E41: Resurtido | F41: =J16 -> -
E42: Auxiliar de Zona DEN | F42: =J17 -> -
E43: Cambios Operativo | F43: =J18 -> -
E44: Supervisor Calzado | F44: =J20 -> -
E45: Imagen | F45: =J31 -> -
...

Sheet DBot
D1: Dictamen de Auditoría a pasillos calzado | AH1: Código: MS-APC/01-17
AH2: Versión: 001
AH3: Vigencia a partir : Mayo 2022
C4: Catalogo: | D4: =Bot!D6 -> BOTAS | R4: Precio promedio por pieza: | W4: 542 | AD4: Fecha de auditoria: | AG4: =Bot!D5 -> 30/Junio/2026
C5: Supervisor de Catalogo: | D5: =Bot!D7 -> Hazminda Garcia | R5: Sugerido de Catalogo | W5: =Bot!F15 -> 0
R6: Tallas del catalogo (linea y linea x inventario) | W6: =B36 -> 5112
D7: Causas de Negado | S7: Incidencias de Auditoria
