Workbook

Sheet MACHOTE SEM
A2: Concentrado por Tienda de Dictamen de Auditoria de Dummy | BV2: Recuperación por tienda y rubro
H3: Semana: | J3: "Semana " | V3: Periodo de evaluación: | BZ3: Semana: | CB3: =J3 -> "Semana " | CN3: Periodo de evaluación: | CQ3: =Y3 -> 0
F5: Causas de Negado | U5: Incidencias de Auditoria | BX5: Causas de Negado | CM5: Incidencias de Auditoria
A6: Tiendas | B6: Calzado | C6: Tallas por pasillo | D6: Tallas por modelo | E6: % de Cobertura de auditoria | F6: Frenteos | G6: Ubicación Revuelta | H6: Bodega Venta (Sin marcar) | I6: Bodega Tapanco | J6: Doble Ubicación | K6: Excedente | L6: Origen | M6: Cambios/Probadores | N6: Negados Sin Recuperar | O6: Exhibición | P6: Bodega Aclaración | Q6: Aduanas | R6: Golden o apartados | S6: Control de calidad | T6: Costo por pasillo | U6: Sin Exhibición | V6: Exhibición fuera de Política | W6: Modelos revuelto | X6: Modelos mal entallados | Y6: Modelos con error de ubicación | Z6: Curva con diferencia en frentes | AA6: Curva con diferencia en fondos | AB6: Curva con diferencia en altura | AC6: Curvas vencidas | AD6: Curvas que no coincide Price Soft vs Piso de Venta | AE6: Curvas faltantes | AF6: Cenefas faltantes | AG6: Cenefas de precio Promoción faltantes | AH6: Cartas disculpa / destallados faltantes | AI6: Fechas de llegada faltantes | AJ6: Resultado de Check List | AK6: Resultado de banderazo surtido | BV6: Tiendas | BW6: Calzado | BX6: Frenteos | BY6: Ubicación Revuelta | BZ6: Bodega Venta (Sin marcar) | CA6: Bodega Tapanco | CB6: Doble Ubicación | CC6: Excedente | CD6: Origen | CE6: Cambios/Probadores | CF6: Negados Sin Recuperar | CG6: Exhibición | CH6: Bodega Aclaración | CI6: Aduanas | CJ6: Golden o apartados | CK6: Control de calidad | CL6: Costo por pasillo | CM6: Sin Exhibición | CN6: Exhibición fuera de Política | CO6: Modelos revuelto | CP6: Modelos mal entallados | CQ6: Modelos con error de ubicación | CR6: Curva con diferencia en frentes | CS6: Curva con diferencia en fondos | CT6: Curva con diferencia en altura | CU6: Curvas vencidas | CV6: Curvas que no coincide Price Soft vs Piso de Venta | CW6: Curvas faltantes | CX6: Cenefas faltantes | CY6: Cenefas de precio Promoción faltantes | CZ6: Cartas disculpa / destallados faltantes | DA6: Fechas de llegada faltantes | EK6: Frenteos | EL6: Ubicación Revuelta | EM6: Bodega Venta (Sin marcar) | EN6: Bodega Tapanco | EO6: Doble Ubicación | EP6: Excedente | EQ6: Origen | ER6: Cambios/Probadores | ES6: Negados Sin Recuperar | ET6: Exhibición | EU6: Bodega Aclaración | EV6: Aduanas | EW6: Golden o apartados | EX6: Control de calidad | EZ6: Frenteos | FA6: Ubicación Revuelta | FB6: Bodega Venta (Sin marcar) | FC6: Bodega Tapanco | FD6: Doble Ubicación | FE6: Excedente | FF6: Origen | FG6: Cambios/Probadores | FH6: Negados Sin Recuperar | FI6: Exhibición | FJ6: Bodega Aclaración | FK6: Aduanas | FL6: Golden o apartados | FM6: Control de calidad
A7: Aguascalientes | C7: =AM56 -> 0 | D7: =AN56 -> 0 | E7: =D7/C7 -> #DIV/0! | F7: =AP56 -> 0 | G7: =AQ56 -> 0 | H7: =AR56 -> 0 | I7: =AS56 -> 0 | J7: =AT56 -> 0 | K7: =AU56 -> 0 | L7: =AV56 -> 0 | M7: =AW56 -> 0 | ... AI7: =BS56 -> 0 | BV7: Aguascalientes | BX7: =DE56 -> 0 | BY7: =DF56 -> 0 | BZ7: =DG56 -> 0 | CA7: =DH56 -> 0 | CB7: =DI56 -> 0 | CC7: =DJ56 -> 0 | CD7: =DK56 -> 0 | CE7: =DL56 -> 0 | ... DA7: =EH56 -> 0 | EJ7: Aguascalientes | EK7: =EK72 -> 0 | EL7: =EL72 -> 0 | EM7: =EM72 -> 0 | EN7: =EN72 -> 0 | EO7: =EO72 -> 0 | EP7: =EP72 -> 0 | EQ7: =EQ72 -> 0 | ER7: =ER72 -> 0 | ... FN7: =FN72 -> 0
A8: Arco Norte | C8: =AM78 -> 0 | D8: =AN78 -> 0 | E8: =D8/C8 -> #DIV/0! | F8: =AP78 -> 0 | G8: =AQ78 -> 0 | H8: =AR78 -> 0 | I8: =AS78 -> 0 | J8: =AT78 -> 0 | K8: =AU78 -> 0 | L8: =AV78 -> 0 | M8: =AW78 -> 0 | ... AI8: =BS78 -> 0 | BV8: Arco Norte | BX8: =DE78 -> 0 | BY8: =DF78 -> 0 | BZ8: =DG78 -> 0 | CA8: =DH78 -> 0 | CB8: =DI78 -> 0 | CC8: =DJ78 -> 0 | CD8: =DK78 -> 0 | CE8: =DL78 -> 0 | ... DA8: =EH78 -> 0 | EJ8: Arco Norte | EK8: =EK94 -> 0 | EL8: =EL94 -> 0 | EM8: =EM94 -> 0 | EN8: =EN94 -> 0 | EO8: =EO94 -> 0 | EP8: =EP94 -> 0 | EQ8: =EQ94 -> 0 | ER8: =ER94 -> 0 | ... FN8: =FN94 -> 0
A9: Centro Historico | C9: =AM100 -> 0 | D9: =AN100 -> 0 | E9: =D9/C9 -> #DIV/0! | F9: =AP100 -> 0 | G9: =AQ100 -> 0 | H9: =AR100 -> 0 | I9: =AS100 -> 0 | J9: =AT100 -> 0 | K9: =AU100 -> 0 | L9: =AV100 -> 0 | M9: =AW100 -> 0 | ... AI9: =BS100 -> 0 | BV9: Centro Historico | BX9: =DE100 -> 0 | BY9: =DF100 -> 0 | BZ9: =DG100 -> 0 | CA9: =DH100 -> 0 | CB9: =DI100 -> 0 | CC9: =DJ100 -> 0 | CD9: =DK100 -> 0 | CE9: =DL100 -> 0 | ... DA9: =EH100 -> 0 | EJ9: Centro Historico | EK9: =EK116 -> 0 | EL9: =EL116 -> 0 | EM9: =EM116 -> 0 | EN9: =EN116 -> 0 | EO9: =EO116 -> 0 | EP9: =EP116 -> 0 | EQ9: =EQ116 -> 0 | ER9: =ER116 -> 0 | ... FN9: =FN116 -> 0
A10: Ecatepec | C10: =AM122 -> 0 | D10: =AN122 -> 0 | E10: =D10/C10 -> #DIV/0! | F10: =AP122 -> 0 | G10: =AQ122 -> 0 | H10: =AR122 -> 0 | I10: =AS122 -> 0 | J10: =AT122 -> 0 | K10: =AU122 -> 0 | L10: =AV122 -> 0 | M10: =AW122 -> 0 | ... AI10: =BS122 -> 0 | BV10: Ecatepec | BX10: =DE122 -> 0 | BY10: =DF122 -> 0 | BZ10: =DG122 -> 0 | CA10: =DH122 -> 0 | CB10: =DI122 -> 0 | CC10: =DJ122 -> 0 | CD10: =DK122 -> 0 | CE10: =DL122 -> 0 | ... DA10: =EH122 -> 0 | EJ10: Ecatepec | EK10: =EK138 -> 0 | EL10: =EL138 -> 0 | EM10: =EM138 -> 0 | EN10: =EN138 -> 0 | EO10: =EO138 -> 0 | EP10: =EP138 -> 0 | EQ10: =EQ138 -> 0 | ER10: =ER138 -> 0 | ... FN10: =FN138 -> 0
A11: Guadalajara | C11: =AM144 -> 0 | D11: =AN144 -> 0 | E11: =D11/C11 -> #DIV/0! | F11: =AP144 -> 0 | G11: =AQ144 -> 0 | H11: =AR144 -> 0 | I11: =AS144 -> 0 | J11: =AT144 -> 0 | K11: =AU144 -> 0 | L11: =AV144 -> 0 | M11: =AW144 -> 0 | ... AI11: =BS144 -> 0 | BV11: Guadalajara | BX11: =DE144 -> 0 | BY11: =DF144 -> 0 | BZ11: =DG144 -> 0 | CA11: =DH144 -> 0 | CB11: =DI144 -> 0 | CC11: =DJ144 -> 0 | CD11: =DK144 -> 0 | CE11: =DL144 -> 0 | ... DA11: =EH144 -> 0 | EJ11: Guadalajara | EK11: =EK160 -> 0 | EL11: =EL160 -> 0 | EM11: =EM160 -> 0 | EN11: =EN160 -> 0 | EO11: =EO160 -> 0 | EP11: =EP160 -> 0 | EQ11: =EQ160 -> 0 | ER11: =ER160 -> 0 | ... FN11: =FN160 -> 0
A12: Ixtapaluca | C12: =AM166 -> 0 | D12: =AN166 -> 0 | E12: =D12/C12 -> #DIV/0! | F12: =AP166 -> 0 | G12: =AQ166 -> 0 | H12: =AR166 -> 0 | I12: =AS166 -> 0 | J12: =AT166 -> 0 | K12: =AU166 -> 0 | L12: =AV166 -> 0 | M12: =AW166 -> 0 | ... AI12: =BS166 -> 0 | BV12: Ixtapaluca | BX12: =DE166 -> 0 | BY12: =DF166 -> 0 | BZ12: =DG166 -> 0 | CA12: =DH166 -> 0 | CB12: =DI166 -> 0 | CC12: =DJ166 -> 0 | CD12: =DK166 -> 0 | CE12: =DL166 -> 0 | ... DA12: =EH166 -> 0 | EJ12: Ixtapaluca | EK12: =EK182 -> 0 | EL12: =EL182 -> 0 | EM12: =EM182 -> 0 | EN12: =EN182 -> 0 | EO12: =EO182 -> 0 | EP12: =EP182 -> 0 | EQ12: =EQ182 -> 0 | ER12: =ER182 -> 0 | ... FN12: =FN182 -> 0
A13: Iztapalapa | C13: =AM188 -> 0 | D13: =AN188 -> 0 | E13: =D13/C13 -> #DIV/0! | F13: =AP188 -> 0 | G13: =AQ188 -> 0 | H13: =AR188 -> 0 | I13: =AS188 -> 0 | J13: =AT188 -> 0 | K13: =AU188 -> 0 | L13: =AV188 -> 0 | M13: =AW188 -> 0 | ... AI13: =BS188 -> 0 | BV13: Iztapalapa | BX13: =DE188 -> 0 | BY13: =DF188 -> 0 | BZ13: =DG188 -> 0 | CA13: =DH188 -> 0 | CB13: =DI188 -> 0 | CC13: =DJ188 -> 0 | CD13: =DK188 -> 0 | CE13: =DL188 -> 0 | ... DA13: =EH188 -> 0 | EJ13: Iztapalapa | EK13: =EK204 -> 0 | EL13: =EL204 -> 0 | EM13: =EM204 -> 0 | EN13: =EN204 -> 0 | EO13: =EO204 -> 0 | EP13: =EP204 -> 0 | EQ13: =EQ204 -> 0 | ER13: =ER204 -> 0 | ... FN13: =FN204 -> 0
A14: León | C14: =AM210 -> 0 | D14: =AN210 -> 0 | E14: =D14/C14 -> #DIV/0! | F14: =AP210 -> 0 | G14: =AQ210 -> 0 | H14: =AR210 -> 0 | I14: =AS210 -> 0 | J14: =AT210 -> 0 | K14: =AU210 -> 0 | L14: =AV210 -> 0 | M14: =AW210 -> 0 | ... AI14: =BS210 -> 0 | BV14: León | BX14: =DE210 -> 0 | BY14: =DF210 -> 0 | BZ14: =DG210 -> 0 | CA14: =DH210 -> 0 | CB14: =DI210 -> 0 | CC14: =DJ210 -> 0 | CD14: =DK210 -> 0 | CE14: =DL210 -> 0 | ... DA14: =EH210 -> 0 | EJ14: León | EK14: =EK226 -> 0 | EL14: =EL226 -> 0 | EM14: =EM226 -> 0 | EN14: =EN226 -> 0 | EO14: =EO226 -> 0 | EP14: =EP226 -> 0 | EQ14: =EQ226 -> 0 | ER14: =ER226 -> 0 | ... FN14: =FN226 -> 0
A15: Miravalle | C15: =AM232 -> 0 | D15: =AN232 -> 0 | E15: =D15/C15 -> #DIV/0! | F15: =AP232 -> 0 | G15: =AQ232 -> 0 | H15: =AR232 -> 0 | I15: =AS232 -> 0 | J15: =AT232 -> 0 | K15: =AU232 -> 0 | L15: =AV232 -> 0 | M15: =AW232 -> 0 | ... AI15: =BS232 -> 0 | BV15: Miravalle | BX15: =DE232 -> 0 | BY15: =DF232 -> 0 | BZ15: =DG232 -> 0 | CA15: =DH232 -> 0 | CB15: =DI232 -> 0 | CC15: =DJ232 -> 0 | CD15: =DK232 -> 0 | CE15: =DL232 -> 0 | ... DA15: =EH232 -> 0 | EJ15: Miravalle | EK15: =EK248 -> 0 | EL15: =EL248 -> 0 | EM15: =EM248 -> 0 | EN15: =EN248 -> 0 | EO15: =EO248 -> 0 | EP15: =EP248 -> 0 | EQ15: =EQ248 -> 0 | ER15: =ER248 -> 0 | ... FN15: =FN248 -> 0
A16: Naucalpan | C16: =AM254 -> 0 | D16: =AN254 -> 0 | E16: =D16/C16 -> #DIV/0! | F16: =AP254 -> 0 | G16: =AQ254 -> 0 | H16: =AR254 -> 0 | I16: =AS254 -> 0 | J16: =AT254 -> 0 | K16: =AU254 -> 0 | L16: =AV254 -> 0 | M16: =AW254 -> 0 | ... AI16: =BS254 -> 0 | BV16: Naucalpan | BX16: =DE254 -> 0 | BY16: =DF254 -> 0 | BZ16: =DG254 -> 0 | CA16: =DH254 -> 0 | CB16: =DI254 -> 0 | CC16: =DJ254 -> 0 | CD16: =DK254 -> 0 | CE16: =DL254 -> 0 | ... DA16: =EH254 -> 0 | EJ16: Naucalpan | EK16: =EK270 -> 0 | EL16: =EL270 -> 0 | EM16: =EM270 -> 0 | EN16: =EN270 -> 0 | EO16: =EO270 -> 0 | EP16: =EP270 -> 0 | EQ16: =EQ270 -> 0 | ER16: =ER270 -> 0 | ... FN16: =FN270 -> 0
A17: Olivar del Conde | C17: =AM276 -> 0 | D17: =AN276 -> 0 | E17: =D17/C17 -> #DIV/0! | F17: =AP276 -> 0 | G17: =AQ276 -> 0 | H17: =AR276 -> 0 | I17: =AS276 -> 0 | J17: =AT276 -> 0 | K17: =AU276 -> 0 | L17: =AV276 -> 0 | M17: =AW276 -> 0 | ... AI17: =BS276 -> 0 | BV17: Olivar del Conde | BX17: =DE276 -> 0 | BY17: =DF276 -> 0 | BZ17: =DG276 -> 0 | CA17: =DH276 -> 0 | CB17: =DI276 -> 0 | CC17: =DJ276 -> 0 | CD17: =DK276 -> 0 | CE17: =DL276 -> 0 | ... DA17: =EH276 -> 0 | EJ17: Olivar del Conde | EK17: =EK292 -> 0 | EL17: =EL292 -> 0 | EM17: =EM292 -> 0 | EN17: =EN292 -> 0 | EO17: =EO292 -> 0 | EP17: =EP292 -> 0 | EQ17: =EQ292 -> 0 | ER17: =ER292 -> 0 | ... FN17: =FN292 -> 0
A18: Puebla | C18: =AM298 -> 0 | D18: =AN298 -> 0 | E18: =D18/C18 -> #DIV/0! | F18: =AP298 -> 0 | G18: =AQ298 -> 0 | H18: =AR298 -> 0 | I18: =AS298 -> 0 | J18: =AT298 -> 0 | K18: =AU298 -> 0 | L18: =AV298 -> 0 | M18: =AW298 -> 0 | ... AI18: =BS298 -> 0 | BV18: Puebla | BX18: =DE298 -> 0 | BY18: =DF298 -> 0 | BZ18: =DG298 -> 0 | CA18: =DH298 -> 0 | CB18: =DI298 -> 0 | CC18: =DJ298 -> 0 | CD18: =DK298 -> 0 | CE18: =DL298 -> 0 | ... DA18: =EH298 -> 0 | EJ18: Puebla | EK18: =EK314 -> 0 | EL18: =EL314 -> 0 | EM18: =EM314 -> 0 | EN18: =EN314 -> 0 | EO18: =EO314 -> 0 | EP18: =EP314 -> 0 | EQ18: =EQ314 -> 0 | ER18: =ER314 -> 0 | ... FN18: =FN314 -> 0
A19: Queretaro | C19: =AM320 -> 0 | D19: =AN320 -> 0 | E19: =D19/C19 -> #DIV/0! | F19: =AP320 -> 0 | G19: =AQ320 -> 0 | H19: =AR320 -> 0 | I19: =AS320 -> 0 | J19: =AT320 -> 0 | K19: =AU320 -> 0 | L19: =AV320 -> 0 | M19: =AW320 -> 0 | ... AI19: =BS320 -> 0 | BV19: Queretaro | BX19: =DE320 -> 0 | BY19: =DF320 -> 0 | BZ19: =DG320 -> 0 | CA19: =DH320 -> 0 | CB19: =DI320 -> 0 | CC19: =DJ320 -> 0 | CD19: =DK320 -> 0 | CE19: =DL320 -> 0 | ... DA19: =EH320 -> 0 | EJ19: Queretaro | EK19: =EK336 -> 0 | EL19: =EL336 -> 0 | EM19: =EM336 -> 0 | EN19: =EN336 -> 0 | EO19: =EO336 -> 0 | EP19: =EP336 -> 0 | EQ19: =EQ336 -> 0 | ER19: =ER336 -> 0 | ... FN19: =FN336 -> 0
A20: Puebla Sur | C20: =AM408 -> 0 | D20: =AN408 -> 0 | E20: =D20/C20 -> #DIV/0! | F20: =AP408 -> 0 | G20: =AQ408 -> 0 | H20: =AR408 -> 0 | I20: =AS408 -> 0 | J20: =AT408 -> 0 | K20: =AU408 -> 0 | L20: =AV408 -> 0 | M20: =AW408 -> 0 | ... AI20: =BS408 -> 0 | BV20: Tijuna | BX20: =DE408 -> 0 | BY20: =DF408 -> 0 | BZ20: =DG408 -> 0 | CA20: =DH408 -> 0 | CB20: =DI408 -> 0 | CC20: =DJ408 -> 0 | CD20: =DK408 -> 0 | CE20: =DL408 -> 0 | ... DA20: =EH408 -> 0 | EJ20: Tijuna | EK20: =EK424 -> 0 | EL20: =EL424 -> 0 | EM20: =EM424 -> 0 | EN20: =EN424 -> 0 | EO20: =EO424 -> 0 | EP20: =EP424 -> 0 | EQ20: =EQ424 -> 0 | ER20: =ER424 -> 0 | ... FN20: =FN424 -> 0
A21: Toluca | C21: =AM342 -> 0 | D21: =AN342 -> 0 | E21: =D21/C21 -> #DIV/0! | F21: =AP342 -> 0 | G21: =AQ342 -> 0 | H21: =AR342 -> 0 | I21: =AS342 -> 0 | J21: =AT342 -> 0 | K21: =AU342 -> 0 | L21: =AV342 -> 0 | M21: =AW342 -> 0 | ... AI21: =BS342 -> 0 | BV21: Toluca | BX21: =DE342 -> 0 | BY21: =DF342 -> 0 | BZ21: =DG342 -> 0 | CA21: =DH342 -> 0 | CB21: =DI342 -> 0 | CC21: =DJ342 -> 0 | CD21: =DK342 -> 0 | CE21: =DL342 -> 0 | ... DA21: =EH342 -> 0 | EJ21: Toluca | EK21: =EK358 -> 0 | EL21: =EL358 -> 0 | EM21: =EM358 -> 0 | EN21: =EN358 -> 0 | EO21: =EO358 -> 0 | EP21: =EP358 -> 0 | EQ21: =EQ358 -> 0 | ER21: =ER358 -> 0 | ... FN21: =FN358 -> 0
A22: Vallejo | C22: =AM364 -> 0 | D22: =AN364 -> 0 | E22: =D22/C22 -> #DIV/0! | F22: =AP364 -> 0 | G22: =AQ364 -> 0 | H22: =AR364 -> 0 | I22: =AS364 -> 0 | J22: =AT364 -> 0 | K22: =AU364 -> 0 | L22: =AV364 -> 0 | M22: =AW364 -> 0 | ... AI22: =BS364 -> 0 | BV22: Vallejo | BX22: =DE364 -> 0 | BY22: =DF364 -> 0 | BZ22: =DG364 -> 0 | CA22: =DH364 -> 0 | CB22: =DI364 -> 0 | CC22: =DJ364 -> 0 | CD22: =DK364 -> 0 | CE22: =DL364 -> 0 | ... DA22: =EH364 -> 0 | EJ22: Vallejo | EK22: =EK380 -> 0 | EL22: =EL380 -> 0 | EM22: =EM380 -> 0 | EN22: =EN380 -> 0 | EO22: =EO380 -> 0 | EP22: =EP380 -> 0 | EQ22: =EQ380 -> 0 | ER22: =ER380 -> 0 | ... FN22: =FN380 -> 0
A23: Veracruz | C23: =AM386 -> 0 | D23: =AN386 -> 0 | E23: =D23/C23 -> #DIV/0! | F23: =AP386 -> 0 | G23: =AQ386 -> 0 | H23: =AR386 -> 0 | I23: =AS386 -> 0 | J23: =AT386 -> 0 | K23: =AU386 -> 0 | L23: =AV386 -> 0 | M23: =AW386 -> 0 | ... AI23: =BS386 -> 0 | BV23: Veracruz | BX23: =DE386 -> 0 | BY23: =DF386 -> 0 | BZ23: =DG386 -> 0 | CA23: =DH386 -> 0 | CB23: =DI386 -> 0 | CC23: =DJ386 -> 0 | CD23: =DK386 -> 0 | CE23: =DL386 -> 0 | ... DA23: =EH386 -> 0 | EJ23: Veracruz | EK23: =EK402 -> 0 | EL23: =EL402 -> 0 | EM23: =EM402 -> 0 | EN23: =EN402 -> 0 | EO23: =EO402 -> 0 | EP23: =EP402 -> 0 | EQ23: =EQ402 -> 0 | ER23: =ER402 -> 0 | ... FN23: =FN402 -> 0
B24: Total | C24: =SUM(C7:C23) -> 0 | D24: =SUM(D7:D23) -> 0 | E24: =D24/C24 -> #DIV/0! | F24: =SUM(F7:F23) -> 0 | H24: =SUM(H7:H23) -> 0 | I24: =SUM(I7:I23) -> 0 | J24: =SUM(J7:J23) -> 0 | K24: =SUM(K7:K23) -> 0 | L24: =SUM(L7:L23) -> 0 | N24: =SUM(N7:N23) -> 0 | O24: =SUM(O7:O23) -> 0 | P24: =SUM(P7:P23) -> 0 | T24: =SUM(F24:P24) -> 0 | U24: =SUM(U7:U23) -> 0 | V24: =SUM(V7:V23) -> 0 | W24: =SUM(W7:W23) -> 0 | X24: =SUM(X7:X23) -> 0 | Y24: =SUM(Y7:Y23) -> 0 | Z24: =SUM(Z7:Z23) -> 0 | AA24: =SUM(AA7:AA23) -> 0 | AB24: =SUM(AB7:AB23) -> 0 | ... AI24: =SUM(AI7:AI23) -> 0 | AJ24: =AVERAGE(AJ7:AJ22) -> #DIV/0! | AK24: =AVERAGE(AK7:AK22) -> #DIV/0! | BW24: Total | BX24: =SUM(BX7:BX23) -> 0 | BZ24: =SUM(BZ7:BZ23) -> 0 | CA24: =SUM(CA7:CA23) -> 0 | CB24: =SUM(CB7:CB23) -> 0 | CC24: =SUM(CC7:CC23) -> 0 | CD24: =SUM(CD7:CD23) -> 0 | CF24: =SUM(CF7:CF23) -> 0 | CG24: =SUM(CG7:CG23) -> 0 | CH24: =SUM(CH7:CH23) -> 0 | CL24: =SUM(BX24:CH24) -> 0 | CM24: =SUM(CM7:CM22) -> 0 | CN24: =SUM(CN7:CN22) -> 0 | CO24: =SUM(CO7:CO22) -> 0 | CP24: =SUM(CP7:CP22) -> 0 | CQ24: =SUM(CQ7:CQ22) -> 0 | CR24: =SUM(CR7:CR22) -> 0 | CS24: =SUM(CS7:CS22) -> 0 | CT24: =SUM(CT7:CT22) -> 0 | ... DA24: =SUM(DA7:DA22) -> 0
C25: Costo de Oportunidad | F25: =SUM(T7:T23) -> 0 | BX25: =SUM(CL7:CL22) -> 0
A27: Concentrado por Tienda de Dictamen de Auditoria de Dummy | BV27: Recuperación por tienda y rubro
F30: Causas de Negado | U30: Incidencias de Auditoria | BX30: Causas de Negado | CM30: Incidencias de Auditoria
A31: Tiendas | B31: Ropa | C31: Tallas por pasillo | D31: Tallas por modelo | E31: % de Cobertura de auditoria | F31: Frenteos | G31: Ubicación Revuelta | H31: Bodega Venta (Sin marcar) | I31: Bodega Tapanco | J31: Doble Ubicación | K31: Excedente | L31: Origen | M31: Cambios/Probadores | N31: Negados Sin Recuperar | O31: Exhibición | P31: Bodega Aclaración | Q31: Aduanas | R31: Golden o apartados | S31: Control de calidad | T31: Costo por pasillo | U31: Sin Exhibición | V31: Exhibición fuera de Política | W31: Modelos revuelto | X31: Modelos mal entallados | Y31: Modelos con error de ubicación | Z31: Curva con diferencia en frentes | AA31: Curva con diferencia en fondos | AB31: Curva con diferencia en altura | AC31: Curvas vencidas | AD31: Curvas que no coincide Price Soft vs Piso de Venta | AE31: Curvas faltantes | AF31: Cenefas faltantes | AG31: Cenefas de precio Promoción faltantes | AH31: Cartas disculpa / destallados faltantes | AI31: Fechas de llegada faltantes | BV31: Tiendas | BW31: Responsable de Catalogo | BX31: Frenteos | BY31: Ubicación Revuelta | BZ31: Bodega Venta (Sin marcar) | CA31: Bodega Tapanco | CB31: Doble Ubicación | CC31: Excedente | CD31: Origen | CE31: Cambios/Probadores | CF31: Negados Sin Recuperar | CG31: Exhibición | CH31: Bodega Aclaración | CI31: Aduanas | CJ31: Golden o apartados | CK31: Control de calidad | CL31: Costo por pasillo | CM31: Sin Exhibición | CN31: Exhibición fuera de Política | CO31: Modelos revuelto | CP31: Modelos mal entallados | CQ31: Modelos con error de ubicación | CR31: Curva con diferencia en frentes | CS31: Curva con diferencia en fondos | CT31: Curva con diferencia en altura | CU31: Curvas vencidas | CV31: Curvas que no coincide Price Soft vs Piso de Venta | CW31: Curvas faltantes | CX31: Cenefas faltantes | CY31: Cenefas de precio Promoción faltantes | CZ31: Cartas disculpa / destallados faltantes | DA31: Fechas de llegada faltantes | EK31: Frenteos | EL31: Ubicación Revuelta | EM31: Bodega Venta (Sin marcar) | EN31: Bodega Tapanco | EO31: Doble Ubicación | EP31: Excedente | EQ31: Origen | ER31: Cambios/Probadores | ES31: Negados Sin Recuperar | ET31: Exhibición | EU31: Bodega Aclaración | EV31: Aduanas | EW31: Golden o apartados | EX31: Control de calidad | EZ31: Frenteos | FA31: Ubicación Revuelta | FB31: Bodega Venta (Sin marcar) | FC31: Bodega Tapanco | FD31: Doble Ubicación | FE31: Excedente | FF31: Origen | FG31: Cambios/Probadores | FH31: Negados Sin Recuperar | FI31: Exhibición | FJ31: Bodega Aclaración | FK31: Aduanas | FL31: Golden o apartados | FM31: Control de calidad
A32: Aguascalientes | C32: =AM58 -> 0 | D32: =AN58 -> 0 | E32: =D32/C32 -> #DIV/0! | F32: =AP58 -> 0 | G32: =AQ58 -> 0 | H32: =AR58 -> 0 | I32: =AS58 -> 0 | J32: =AT58 -> 0 | K32: =AU58 -> 0 | L32: =AV58 -> 0 | M32: =AW58 -> 0 | ... AI32: =BS58 -> 0 | BV32: Aguascalientes | BX32: =DE58 -> 0 | BY32: =DF58 -> 0 | BZ32: =DG58 -> 0 | CA32: =DH58 -> 0 | CB32: =DI58 -> 0 | CC32: =DJ58 -> 0 | CD32: =DK58 -> 0 | CE32: =DL58 -> 0 | ... DA32: =EH58 -> 0 | EJ32: Aguascalientes | EK32: =EK73 -> 0 | EL32: =EL73 -> 0 | EM32: =EM73 -> 0 | EN32: =EN73 -> 0 | EO32: =EO73 -> 0 | EP32: =EP73 -> 0 | EQ32: =EQ73 -> 0 | ER32: =ER73 -> 0 | ... FN32: =FN73 -> 0
A33: Arco Norte | C33: =AM80 -> 0 | D33: =AN80 -> 0 | E33: =D33/C33 -> #DIV/0! | F33: =AP80 -> 0 | G33: =AQ80 -> 0 | H33: =AR80 -> 0 | I33: =AS80 -> 0 | J33: =AT80 -> 0 | K33: =AU80 -> 0 | L33: =AV80 -> 0 | M33: =AW80 -> 0 | ... AI33: =BS80 -> 0 | BV33: Arco Norte | BX33: =DE80 -> 0 | BY33: =DF80 -> 0 | BZ33: =DG80 -> 0 | CA33: =DH80 -> 0 | CB33: =DI80 -> 0 | CC33: =DJ80 -> 0 | CD33: =DK80 -> 0 | CE33: =DL80 -> 0 | ... DA33: =EH80 -> 0 | EJ33: Arco Norte | EK33: =EK95 -> 0 | EL33: =EL95 -> 0 | EM33: =EM95 -> 0 | EN33: =EN95 -> 0 | EO33: =EO95 -> 0 | EP33: =EP95 -> 0 | EQ33: =EQ95 -> 0 | ER33: =ER95 -> 0 | ... FN33: =FN95 -> 0
A34: Centro Historico | C34: =AM102 -> 0 | D34: =AN102 -> 0 | E34: =D34/C34 -> #DIV/0! | F34: =AP102 -> 0 | G34: =AQ102 -> 0 | H34: =AR102 -> 0 | I34: =AS102 -> 0 | J34: =AT102 -> 0 | K34: =AU102 -> 0 | L34: =AV102 -> 0 | M34: =AW102 -> 0 | ... AI34: =BS102 -> 0 | BV34: Centro Historico | BX34: =DE102 -> 0 | BY34: =DF102 -> 0 | BZ34: =DG102 -> 0 | CA34: =DH102 -> 0 | CB34: =DI102 -> 0 | CC34: =DJ102 -> 0 | CD34: =DK102 -> 0 | CE34: =DL102 -> 0 | ... DA34: =EH102 -> 0 | EJ34: Centro Historico | EK34: =EK117 -> 0 | EL34: =EL117 -> 0 | EM34: =EM117 -> 0 | EN34: =EN117 -> 0 | EO34: =EO117 -> 0 | EP34: =EP117 -> 0 | EQ34: =EQ117 -> 0 | ER34: =ER117 -> 0 | ... FN34: =FN117 -> 0
A35: Ecatepec | C35: =AM124 -> 0 | D35: =AN124 -> 0 | E35: =D35/C35 -> #DIV/0! | F35: =AP124 -> 0 | G35: =AQ124 -> 0 | H35: =AR124 -> 0 | I35: =AS124 -> 0 | J35: =AT124 -> 0 | K35: =AU124 -> 0 | L35: =AV124 -> 0 | M35: =AW124 -> 0 | ... AI35: =BS124 -> 0 | BV35: Ecatepec | BX35: =DE124 -> 0 | BY35: =DF124 -> 0 | BZ35: =DG124 -> 0 | CA35: =DH124 -> 0 | CB35: =DI124 -> 0 | CC35: =DJ124 -> 0 | CD35: =DK124 -> 0 | CE35: =DL124 -> 0 | ... DA35: =EH124 -> 0 | EJ35: Ecatepec | EK35: =EK139 -> 0 | EL35: =EL139 -> 0 | EM35: =EM139 -> 0 | EN35: =EN139 -> 0 | EO35: =EO139 -> 0 | EP35: =EP139 -> 0 | EQ35: =EQ139 -> 0 | ER35: =ER139 -> 0 | ... FN35: =FN139 -> 0
A36: Guadalajara | C36: =AM146 -> 0 | D36: =AN146 -> 0 | E36: =D36/C36 -> #DIV/0! | F36: =AP146 -> 0 | G36: =AQ146 -> 0 | H36: =AR146 -> 0 | I36: =AS146 -> 0 | J36: =AT146 -> 0 | K36: =AU146 -> 0 | L36: =AV146 -> 0 | M36: =AW146 -> 0 | ... AI36: =BS146 -> 0 | BV36: Guadalajara | BX36: =DE146 -> 0 | BY36: =DF146 -> 0 | BZ36: =DG146 -> 0 | CA36: =DH146 -> 0 | CB36: =DI146 -> 0 | CC36: =DJ146 -> 0 | CD36: =DK146 -> 0 | CE36: =DL146 -> 0 | ... DA36: =EH146 -> 0 | EJ36: Guadalajara | EK36: =EK161 -> 0 | EL36: =EL161 -> 0 | EM36: =EM161 -> 0 | EN36: =EN161 -> 0 | EO36: =EO161 -> 0 | EP36: =EP161 -> 0 | EQ36: =EQ161 -> 0 | ER36: =ER161 -> 0 | ... FN36: =FN161 -> 0
A37: Ixtapaluca | C37: =AM168 -> 0 | D37: =AN168 -> 0 | E37: =D37/C37 -> #DIV/0! | F37: =AP168 -> 0 | G37: =AQ168 -> 0 | H37: =AR168 -> 0 | I37: =AS168 -> 0 | J37: =AT168 -> 0 | K37: =AU168 -> 0 | L37: =AV168 -> 0 | M37: =AW168 -> 0 | ... AI37: =BS168 -> 0 | BV37: Ixtapaluca | BX37: =DE168 -> 0 | BY37: =DF168 -> 0 | BZ37: =DG168 -> 0 | CA37: =DH168 -> 0 | CB37: =DI168 -> 0 | CC37: =DJ168 -> 0 | CD37: =DK168 -> 0 | CE37: =DL168 -> 0 | ... DA37: =EH168 -> 0 | EJ37: Ixtapaluca | EK37: =EK183 -> 0 | EL37: =EL183 -> 0 | EM37: =EM183 -> 0 | EN37: =EN183 -> 0 | EO37: =EO183 -> 0 | EP37: =EP183 -> 0 | EQ37: =EQ183 -> 0 | ER37: =ER183 -> 0 | ... FN37: =FN183 -> 0
A38: Iztapalapa | C38: =AM190 -> 0 | D38: =AN190 -> 0 | E38: =D38/C38 -> #DIV/0! | F38: =AP190 -> 0 | G38: =AQ190 -> 0 | H38: =AR190 -> 0 | I38: =AS190 -> 0 | J38: =AT190 -> 0 | K38: =AU190 -> 0 | L38: =AV190 -> 0 | M38: =AW190 -> 0 | ... AI38: =BS190 -> 0 | BV38: Iztapalapa | BX38: =DE190 -> 0 | BY38: =DF190 -> 0 | BZ38: =DG190 -> 0 | CA38: =DH190 -> 0 | CB38: =DI190 -> 0 | CC38: =DJ190 -> 0 | CD38: =DK190 -> 0 | CE38: =DL190 -> 0 | ... DA38: =EH190 -> 0 | EJ38: Iztapalapa | EK38: =EK205 -> 0 | EL38: =EL205 -> 0 | EM38: =EM205 -> 0 | EN38: =EN205 -> 0 | EO38: =EO205 -> 0 | EP38: =EP205 -> 0 | EQ38: =EQ205 -> 0 | ER38: =ER205 -> 0 | ... FN38: =FN205 -> 0
A39: León | C39: =AM212 -> 0 | D39: =AN212 -> 0 | E39: =D39/C39 -> #DIV/0! | F39: =AP212 -> 0 | G39: =AQ212 -> 0 | H39: =AR212 -> 0 | I39: =AS212 -> 0 | J39: =AT212 -> 0 | K39: =AU212 -> 0 | L39: =AV212 -> 0 | M39: =AW212 -> 0 | ... AI39: =BS212 -> 0 | BV39: León | BX39: =DE212 -> 0 | BY39: =DF212 -> 0 | BZ39: =DG212 -> 0 | CA39: =DH212 -> 0 | CB39: =DI212 -> 0 | CC39: =DJ212 -> 0 | CD39: =DK212 -> 0 | CE39: =DL212 -> 0 | ... DA39: =EH212 -> 0 | EJ39: León | EK39: =EK227 -> 0 | EL39: =EL227 -> 0 | EM39: =EM227 -> 0 | EN39: =EN227 -> 0 | EO39: =EO227 -> 0 | EP39: =EP227 -> 0 | EQ39: =EQ227 -> 0 | ER39: =ER227 -> 0 | ... FN39: =FN227 -> 0
A40: Miravalle | C40: =AM234 -> 0 | D40: =AN234 -> 0 | E40: =D40/C40 -> #DIV/0! | F40: =AP234 -> 0 | G40: =AQ234 -> 0 | H40: =AR234 -> 0 | I40: =AS234 -> 0 | J40: =AT234 -> 0 | K40: =AU234 -> 0 | L40: =AV234 -> 0 | M40: =AW234 -> 0 | ... AI40: =BS234 -> 0 | BV40: Miravalle | BX40: =DE234 -> 0 | BY40: =DF234 -> 0 | BZ40: =DG234 -> 0 | CA40: =DH234 -> 0 | CB40: =DI234 -> 0 | CC40: =DJ234 -> 0 | CD40: =DK234 -> 0 | CE40: =DL234 -> 0 | ... DA40: =EH234 -> 0 | EJ40: Miravalle | EK40: =EK249 -> 0 | EL40: =EL249 -> 0 | EM40: =EM249 -> 0 | EN40: =EN249 -> 0 | EO40: =EO249 -> 0 | EP40: =EP249 -> 0 | EQ40: =EQ249 -> 0 | ER40: =ER249 -> 0 | ... FN40: =FN249 -> 0
A41: Naucalpan | C41: =AM256 -> 0 | D41: =AN256 -> 0 | E41: =D41/C41 -> #DIV/0! | F41: =AP256 -> 0 | G41: =AQ256 -> 0 | H41: =AR256 -> 0 | I41: =AS256 -> 0 | J41: =AT256 -> 0 | K41: =AU256 -> 0 | L41: =AV256 -> 0 | M41: =AW256 -> 0 | ... AI41: =BS256 -> 0 | BV41: Naucalpan | BX41: =DE256 -> 0 | BY41: =DF256 -> 0 | BZ41: =DG256 -> 0 | CA41: =DH256 -> 0 | CB41: =DI256 -> 0 | CC41: =DJ256 -> 0 | CD41: =DK256 -> 0 | CE41: =DL256 -> 0 | ... DA41: =EH256 -> 0 | EJ41: Naucalpan | EK41: =EK271 -> 0 | EL41: =EL271 -> 0 | EM41: =EM271 -> 0 | EN41: =EN271 -> 0 | EO41: =EO271 -> 0 | EP41: =EP271 -> 0 | EQ41: =EQ271 -> 0 | ER41: =ER271 -> 0 | ... FN41: =FN271 -> 0
A42: Olivar del Conde | C42: =AM278 -> 0 | D42: =AN278 -> 0 | E42: =D42/C42 -> #DIV/0! | F42: =AP278 -> 0 | G42: =AQ278 -> 0 | H42: =AR278 -> 0 | I42: =AS278 -> 0 | J42: =AT278 -> 0 | K42: =AU278 -> 0 | L42: =AV278 -> 0 | M42: =AW278 -> 0 | ... AI42: =BS278 -> 0 | BV42: Olivar del Conde | BX42: =DE278 -> 0 | BY42: =DF278 -> 0 | BZ42: =DG278 -> 0 | CA42: =DH278 -> 0 | CB42: =DI278 -> 0 | CC42: =DJ278 -> 0 | CD42: =DK278 -> 0 | CE42: =DL278 -> 0 | ... DA42: =EH278 -> 0 | EJ42: Olivar del Conde | EK42: =EK293 -> 0 | EL42: =EL293 -> 0 | EM42: =EM293 -> 0 | EN42: =EN293 -> 0 | EO42: =EO293 -> 0 | EP42: =EP293 -> 0 | EQ42: =EQ293 -> 0 | ER42: =ER293 -> 0 | ... FN42: =FN293 -> 0
A43: Puebla | C43: =AM300 -> 0 | D43: =AN300 -> 0 | E43: =D43/C43 -> #DIV/0! | F43: =AP300 -> 0 | G43: =AQ300 -> 0 | H43: =AR300 -> 0 | I43: =AS300 -> 0 | J43: =AT300 -> 0 | K43: =AU300 -> 0 | L43: =AV300 -> 0 | M43: =AW300 -> 0 | ... AI43: =BS300 -> 0 | BV43: Puebla | BX43: =DE300 -> 0 | BY43: =DF300 -> 0 | BZ43: =DG300 -> 0 | CA43: =DH300 -> 0 | CB43: =DI300 -> 0 | CC43: =DJ300 -> 0 | CD43: =DK300 -> 0 | CE43: =DL300 -> 0 | ... DA43: =EH300 -> 0 | EJ43: Puebla | EK43: =EK315 -> 0 | EL43: =EL315 -> 0 | EM43: =EM315 -> 0 | EN43: =EN315 -> 0 | EO43: =EO315 -> 0 | EP43: =EP315 -> 0 | EQ43: =EQ315 -> 0 | ER43: =ER315 -> 0 | ... FN43: =FN315 -> 0
A44: Queretaro | C44: =AM322 -> 0 | D44: =AN322 -> 0 | E44: =D44/C44 -> #DIV/0! | F44: =AP322 -> 0 | G44: =AQ322 -> 0 | H44: =AR322 -> 0 | I44: =AS322 -> 0 | J44: =AT322 -> 0 | K44: =AU322 -> 0 | L44: =AV322 -> 0 | M44: =AW322 -> 0 | ... AI44: =BS322 -> 0 | BV44: Queretaro | BX44: =DE322 -> 0 | BY44: =DF322 -> 0 | BZ44: =DG322 -> 0 | CA44: =DH322 -> 0 | CB44: =DI322 -> 0 | CC44: =DJ322 -> 0 | CD44: =DK322 -> 0 | CE44: =DL322 -> 0 | ... DA44: =EH322 -> 0 | EJ44: Queretaro | EK44: =EK337 -> 0 | EL44: =EL337 -> 0 | EM44: =EM337 -> 0 | EN44: =EN337 -> 0 | EO44: =EO337 -> 0 | EP44: =EP337 -> 0 | EQ44: =EQ337 -> 0 | ER44: =ER337 -> 0 | ... FN44: =FN337 -> 0
A45: Puebla Sur | C45: =AM410 -> 0 | D45: =AN410 -> 0 | E45: =D45/C45 -> #DIV/0! | F45: =AP410 -> 0 | G45: =AQ410 -> 0 | H45: =AR410 -> 0 | I45: =AS410 -> 0 | J45: =AT410 -> 0 | K45: =AU410 -> 0 | L45: =AV410 -> 0 | M45: =AW410 -> 0 | ... AI45: =BS410 -> 0 | BV45: Tijuna | BX45: =DE410 -> 0 | BY45: =DF410 -> 0 | BZ45: =DG410 -> 0 | CA45: =DH410 -> 0 | CB45: =DI410 -> 0 | CC45: =DJ410 -> 0 | CD45: =DK410 -> 0 | CE45: =DL410 -> 0 | ... DA45: =EH410 -> 0 | EJ45: Tijuna | EK45: =EK425 -> 0 | EL45: =EL425 -> 0 | EM45: =EM425 -> 0 | EN45: =EN425 -> 0 | EO45: =EO425 -> 0 | EP45: =EP425 -> 0 | EQ45: =EQ425 -> 0 | ER45: =ER425 -> 0 | ... FN45: =FN425 -> 0
...

Sheet SEMANA
A2: Concentrado por Tienda de Dictamen de Auditoria de Dummy | BV2: Recuperación por tienda y rubro
H3: Semana: | J3: "Semana " | V3: Periodo de evaluación: | BZ3: Semana: | CB3: =J3 -> "Semana " | CN3: Periodo de evaluación: | CQ3: =Y3 -> 0
F5: Causas de Negado | U5: Incidencias de Auditoria | BX5: Causas de Negado | CM5: Incidencias de Auditoria
A6: Tiendas | B6: Calzado | C6: Tallas por pasillo | D6: Tallas por modelo | E6: % de Cobertura de auditoria | F6: Frenteos | G6: Ubicación Revuelta | H6: Bodega Venta (Sin marcar) | I6: Bodega Tapanco | J6: Doble Ubicación | K6: Excedente | L6: Origen | M6: Cambios/Probadores | N6: Negados Sin Recuperar | O6: Exhibición | P6: Bodega Aclaración | Q6: Aduanas | R6: Golden o apartados | S6: Control de calidad | T6: Costo por pasillo | U6: Sin Exhibición | V6: Exhibición fuera de Política | W6: Modelos revuelto | X6: Modelos mal entallados | Y6: Modelos con error de ubicación | Z6: Curva con diferencia en frentes | AA6: Curva con diferencia en fondos | AB6: Curva con diferencia en altura | AC6: Curvas vencidas | AD6: Curvas que no coincide Price Soft vs Piso de Venta | AE6: Curvas faltantes | AF6: Cenefas faltantes | AG6: Cenefas de precio Promoción faltantes | AH6: Cartas disculpa / destallados faltantes | AI6: Fechas de llegada faltantes | AJ6: Resultado de Check List | AK6: Resultado de banderazo surtido | BV6: Tiendas | BW6: Calzado | BX6: Frenteos | BY6: Ubicación Revuelta | BZ6: Bodega Venta (Sin marcar) | CA6: Bodega Tapanco | CB6: Doble Ubicación | CC6: Excedente | CD6: Origen | CE6: Cambios/Probadores | CF6: Negados Sin Recuperar | CG6: Exhibición | CH6: Bodega Aclaración | CI6: Aduanas | CJ6: Golden o apartados | CK6: Control de calidad | CL6: Costo por pasillo | CM6: Sin Exhibición | CN6: Exhibición fuera de Política | CO6: Modelos revuelto | CP6: Modelos mal entallados | CQ6: Modelos con error de ubicación | CR6: Curva con diferencia en frentes | CS6: Curva con diferencia en fondos | CT6: Curva con diferencia en altura | CU6: Curvas vencidas | CV6: Curvas que no coincide Price Soft vs Piso de Venta | CW6: Curvas faltantes | CX6: Cenefas faltantes | CY6: Cenefas de precio Promoción faltantes | CZ6: Cartas disculpa / destallados faltantes | DA6: Fechas de llegada faltantes | EK6: Frenteos | EL6: Ubicación Revuelta | EM6: Bodega Venta (Sin marcar) | EN6: Bodega Tapanco | EO6: Doble Ubicación | EP6: Excedente | EQ6: Origen | ER6: Cambios/Probadores | ES6: Negados Sin Recuperar | ET6: Exhibición | EU6: Bodega Aclaración | EV6: Aduanas | EW6: Golden o apartados | EX6: Control de calidad | EZ6: Frenteos | FA6: Ubicación Revuelta | FB6: Bodega Venta (Sin marcar) | FC6: Bodega Tapanco | FD6: Doble Ubicación | FE6: Excedente | FF6: Origen | FG6: Cambios/Probadores | FH6: Negados Sin Recuperar | FI6: Exhibición | FJ6: Bodega Aclaración | FK6: Aduanas | FL6: Golden o apartados | FM6: Control de calidad
A7: Aguascalientes | C7: =AM56 -> 0 | D7: =AN56 -> 0 | E7: =D7/C7 -> #DIV/0! | F7: =AP56 -> 0 | G7: =AQ56 -> 0 | H7: =AR56 -> 0 | I7: =AS56 -> 0 | J7: =AT56 -> 0 | K7: =AU56 -> 0 | L7: =AV56 -> 0 | M7: =AW56 -> 0 | ... AI7: =BS56 -> 0 | BV7: Aguascalientes | BX7: =DE56 -> 0 | BY7: =DF56 -> 0 | BZ7: =DG56 -> 0 | CA7: =DH56 -> 0 | CB7: =DI56 -> 0 | CC7: =DJ56 -> 0 | CD7: =DK56 -> 0 | CE7: =DL56 -> 0 | ... DA7: =EH56 -> 0 | EJ7: Aguascalientes | EK7: =EK72 -> 0 | EL7: =EL72 -> 0 | EM7: =EM72 -> 0 | EN7: =EN72 -> 0 | EO7: =EO72 -> 0 | EP7: =EP72 -> 0 | EQ7: =EQ72 -> 0 | ER7: =ER72 -> 0 | ... FN7: =FN72 -> 0
A8: Arco Norte | C8: =AM78 -> 0 | D8: =AN78 -> 0 | E8: =D8/C8 -> #DIV/0! | F8: =AP78 -> 0 | G8: =AQ78 -> 0 | H8: =AR78 -> 0 | I8: =AS78 -> 0 | J8: =AT78 -> 0 | K8: =AU78 -> 0 | L8: =AV78 -> 0 | M8: =AW78 -> 0 | ... AI8: =BS78 -> 0 | BV8: Arco Norte | BX8: =DE78 -> 0 | BY8: =DF78 -> 0 | BZ8: =DG78 -> 0 | CA8: =DH78 -> 0 | CB8: =DI78 -> 0 | CC8: =DJ78 -> 0 | CD8: =DK78 -> 0 | CE8: =DL78 -> 0 | ... DA8: =EH78 -> 0 | EJ8: Arco Norte | EK8: =EK94 -> 0 | EL8: =EL94 -> 0 | EM8: =EM94 -> 0 | EN8: =EN94 -> 0 | EO8: =EO94 -> 0 | EP8: =EP94 -> 0 | EQ8: =EQ94 -> 0 | ER8: =ER94 -> 0 | ... FN8: =FN94 -> 0
A9: Centro Historico | C9: =AM100 -> 0 | D9: =AN100 -> 0 | E9: =D9/C9 -> #DIV/0! | F9: =AP100 -> 0 | G9: =AQ100 -> 0 | H9: =AR100 -> 0 | I9: =AS100 -> 0 | J9: =AT100 -> 0 | K9: =AU100 -> 0 | L9: =AV100 -> 0 | M9: =AW100 -> 0 | ... AI9: =BS100 -> 0 | BV9: Centro Historico | BX9: =DE100 -> 0 | BY9: =DF100 -> 0 | BZ9: =DG100 -> 0 | CA9: =DH100 -> 0 | CB9: =DI100 -> 0 | CC9: =DJ100 -> 0 | CD9: =DK100 -> 0 | CE9: =DL100 -> 0 | ... DA9: =EH100 -> 0 | EJ9: Centro Historico | EK9: =EK116 -> 0 | EL9: =EL116 -> 0 | EM9: =EM116 -> 0 | EN9: =EN116 -> 0 | EO9: =EO116 -> 0 | EP9: =EP116 -> 0 | EQ9: =EQ116 -> 0 | ER9: =ER116 -> 0 | ... FN9: =FN116 -> 0
A10: Ecatepec | C10: =AM122 -> 0 | D10: =AN122 -> 0 | E10: =D10/C10 -> #DIV/0! | F10: =AP122 -> 0 | G10: =AQ122 -> 0 | H10: =AR122 -> 0 | I10: =AS122 -> 0 | J10: =AT122 -> 0 | K10: =AU122 -> 0 | L10: =AV122 -> 0 | M10: =AW122 -> 0 | ... AI10: =BS122 -> 0 | BV10: Ecatepec | BX10: =DE122 -> 0 | BY10: =DF122 -> 0 | BZ10: =DG122 -> 0 | CA10: =DH122 -> 0 | CB10: =DI122 -> 0 | CC10: =DJ122 -> 0 | CD10: =DK122 -> 0 | CE10: =DL122 -> 0 | ... DA10: =EH122 -> 0 | EJ10: Ecatepec | EK10: =EK138 -> 0 | EL10: =EL138 -> 0 | EM10: =EM138 -> 0 | EN10: =EN138 -> 0 | EO10: =EO138 -> 0 | EP10: =EP138 -> 0 | EQ10: =EQ138 -> 0 | ER10: =ER138 -> 0 | ... FN10: =FN138 -> 0
A11: Guadalajara | C11: =AM144 -> 0 | D11: =AN144 -> 0 | E11: =D11/C11 -> #DIV/0! | F11: =AP144 -> 0 | G11: =AQ144 -> 0 | H11: =AR144 -> 0 | I11: =AS144 -> 0 | J11: =AT144 -> 0 | K11: =AU144 -> 0 | L11: =AV144 -> 0 | M11: =AW144 -> 0 | ... AI11: =BS144 -> 0 | BV11: Guadalajara | BX11: =DE144 -> 0 | BY11: =DF144 -> 0 | BZ11: =DG144 -> 0 | CA11: =DH144 -> 0 | CB11: =DI144 -> 0 | CC11: =DJ144 -> 0 | CD11: =DK144 -> 0 | CE11: =DL144 -> 0 | ... DA11: =EH144 -> 0 | EJ11: Guadalajara | EK11: =EK160 -> 0 | EL11: =EL160 -> 0 | EM11: =EM160 -> 0 | EN11: =EN160 -> 0 | EO11: =EO160 -> 0 | EP11: =EP160 -> 0 | EQ11: =EQ160 -> 0 | ER11: =ER160 -> 0 | ... FN11: =FN160 -> 0
A12: Ixtapaluca | C12: =AM166 -> 0 | D12: =AN166 -> 0 | E12: =D12/C12 -> #DIV/0! | F12: =AP166 -> 0 | G12: =AQ166 -> 0 | H12: =AR166 -> 0 | I12: =AS166 -> 0 | J12: =AT166 -> 0 | K12: =AU166 -> 0 | L12: =AV166 -> 0 | M12: =AW166 -> 0 | ... AI12: =BS166 -> 0 | BV12: Ixtapaluca | BX12: =DE166 -> 0 | BY12: =DF166 -> 0 | BZ12: =DG166 -> 0 | CA12: =DH166 -> 0 | CB12: =DI166 -> 0 | CC12: =DJ166 -> 0 | CD12: =DK166 -> 0 | CE12: =DL166 -> 0 | ... DA12: =EH166 -> 0 | EJ12: Ixtapaluca | EK12: =EK182 -> 0 | EL12: =EL182 -> 0 | EM12: =EM182 -> 0 | EN12: =EN182 -> 0 | EO12: =EO182 -> 0 | EP12: =EP182 -> 0 | EQ12: =EQ182 -> 0 | ER12: =ER182 -> 0 | ... FN12: =FN182 -> 0
A13: Iztapalapa | C13: =AM188 -> 0 | D13: =AN188 -> 0 | E13: =D13/C13 -> #DIV/0! | F13: =AP188 -> 0 | G13: =AQ188 -> 0 | H13: =AR188 -> 0 | I13: =AS188 -> 0 | J13: =AT188 -> 0 | K13: =AU188 -> 0 | L13: =AV188 -> 0 | M13: =AW188 -> 0 | ... AI13: =BS188 -> 0 | BV13: Iztapalapa | BX13: =DE188 -> 0 | BY13: =DF188 -> 0 | BZ13: =DG188 -> 0 | CA13: =DH188 -> 0 | CB13: =DI188 -> 0 | CC13: =DJ188 -> 0 | CD13: =DK188 -> 0 | CE13: =DL188 -> 0 | ... DA13: =EH188 -> 0 | EJ13: Iztapalapa | EK13: =EK204 -> 0 | EL13: =EL204 -> 0 | EM13: =EM204 -> 0 | EN13: =EN204 -> 0 | EO13: =EO204 -> 0 | EP13: =EP204 -> 0 | EQ13: =EQ204 -> 0 | ER13: =ER204 -> 0 | ... FN13: =FN204 -> 0
A14: León | C14: =AM210 -> 0 | D14: =AN210 -> 0 | E14: =D14/C14 -> #DIV/0! | F14: =AP210 -> 0 | G14: =AQ210 -> 0 | H14: =AR210 -> 0 | I14: =AS210 -> 0 | J14: =AT210 -> 0 | K14: =AU210 -> 0 | L14: =AV210 -> 0 | M14: =AW210 -> 0 | ... AI14: =BS210 -> 0 | BV14: León | BX14: =DE210 -> 0 | BY14: =DF210 -> 0 | BZ14: =DG210 -> 0 | CA14: =DH210 -> 0 | CB14: =DI210 -> 0 | CC14: =DJ210 -> 0 | CD14: =DK210 -> 0 | CE14: =DL210 -> 0 | ... DA14: =EH210 -> 0 | EJ14: León | EK14: =EK226 -> 0 | EL14: =EL226 -> 0 | EM14: =EM226 -> 0 | EN14: =EN226 -> 0 | EO14: =EO226 -> 0 | EP14: =EP226 -> 0 | EQ14: =EQ226 -> 0 | ER14: =ER226 -> 0 | ... FN14: =FN226 -> 0
A15: Miravalle | C15: =AM232 -> 0 | D15: =AN232 -> 0 | E15: =D15/C15 -> #DIV/0! | F15: =AP232 -> 0 | G15: =AQ232 -> 0 | H15: =AR232 -> 0 | I15: =AS232 -> 0 | J15: =AT232 -> 0 | K15: =AU232 -> 0 | L15: =AV232 -> 0 | M15: =AW232 -> 0 | ... AI15: =BS232 -> 0 | BV15: Miravalle | BX15: =DE232 -> 0 | BY15: =DF232 -> 0 | BZ15: =DG232 -> 0 | CA15: =DH232 -> 0 | CB15: =DI232 -> 0 | CC15: =DJ232 -> 0 | CD15: =DK232 -> 0 | CE15: =DL232 -> 0 | ... DA15: =EH232 -> 0 | EJ15: Miravalle | EK15: =EK248 -> 0 | EL15: =EL248 -> 0 | EM15: =EM248 -> 0 | EN15: =EN248 -> 0 | EO15: =EO248 -> 0 | EP15: =EP248 -> 0 | EQ15: =EQ248 -> 0 | ER15: =ER248 -> 0 | ... FN15: =FN248 -> 0
A16: Naucalpan | C16: =AM254 -> 0 | D16: =AN254 -> 0 | E16: =D16/C16 -> #DIV/0! | F16: =AP254 -> 0 | G16: =AQ254 -> 0 | H16: =AR254 -> 0 | I16: =AS254 -> 0 | J16: =AT254 -> 0 | K16: =AU254 -> 0 | L16: =AV254 -> 0 | M16: =AW254 -> 0 | ... AI16: =BS254 -> 0 | BV16: Naucalpan | BX16: =DE254 -> 0 | BY16: =DF254 -> 0 | BZ16: =DG254 -> 0 | CA16: =DH254 -> 0 | CB16: =DI254 -> 0 | CC16: =DJ254 -> 0 | CD16: =DK254 -> 0 | CE16: =DL254 -> 0 | ... DA16: =EH254 -> 0 | EJ16: Naucalpan | EK16: =EK270 -> 0 | EL16: =EL270 -> 0 | EM16: =EM270 -> 0 | EN16: =EN270 -> 0 | EO16: =EO270 -> 0 | EP16: =EP270 -> 0 | EQ16: =EQ270 -> 0 | ER16: =ER270 -> 0 | ... FN16: =FN270 -> 0
A17: Olivar del Conde | C17: =AM276 -> 0 | D17: =AN276 -> 0 | E17: =D17/C17 -> #DIV/0! | F17: =AP276 -> 0 | G17: =AQ276 -> 0 | H17: =AR276 -> 0 | I17: =AS276 -> 0 | J17: =AT276 -> 0 | K17: =AU276 -> 0 | L17: =AV276 -> 0 | M17: =AW276 -> 0 | ... AI17: =BS276 -> 0 | BV17: Olivar del Conde | BX17: =DE276 -> 0 | BY17: =DF276 -> 0 | BZ17: =DG276 -> 0 | CA17: =DH276 -> 0 | CB17: =DI276 -> 0 | CC17: =DJ276 -> 0 | CD17: =DK276 -> 0 | CE17: =DL276 -> 0 | ... DA17: =EH276 -> 0 | EJ17: Olivar del Conde | EK17: =EK292 -> 0 | EL17: =EL292 -> 0 | EM17: =EM292 -> 0 | EN17: =EN292 -> 0 | EO17: =EO292 -> 0 | EP17: =EP292 -> 0 | EQ17: =EQ292 -> 0 | ER17: =ER292 -> 0 | ... FN17: =FN292 -> 0
A18: Puebla | C18: =AM298 -> 0 | D18: =AN298 -> 0 | E18: =D18/C18 -> #DIV/0! | F18: =AP298 -> 0 | G18: =AQ298 -> 0 | H18: =AR298 -> 0 | I18: =AS298 -> 0 | J18: =AT298 -> 0 | K18: =AU298 -> 0 | L18: =AV298 -> 0 | M18: =AW298 -> 0 | ... AI18: =BS298 -> 0 | BV18: Puebla | BX18: =DE298 -> 0 | BY18: =DF298 -> 0 | BZ18: =DG298 -> 0 | CA18: =DH298 -> 0 | CB18: =DI298 -> 0 | CC18: =DJ298 -> 0 | CD18: =DK298 -> 0 | CE18: =DL298 -> 0 | ... DA18: =EH298 -> 0 | EJ18: Puebla | EK18: =EK314 -> 0 | EL18: =EL314 -> 0 | EM18: =EM314 -> 0 | EN18: =EN314 -> 0 | EO18: =EO314 -> 0 | EP18: =EP314 -> 0 | EQ18: =EQ314 -> 0 | ER18: =ER314 -> 0 | ... FN18: =FN314 -> 0
A19: Queretaro | C19: =AM320 -> 0 | D19: =AN320 -> 0 | E19: =D19/C19 -> #DIV/0! | F19: =AP320 -> 0 | G19: =AQ320 -> 0 | H19: =AR320 -> 0 | I19: =AS320 -> 0 | J19: =AT320 -> 0 | K19: =AU320 -> 0 | L19: =AV320 -> 0 | M19: =AW320 -> 0 | ... AI19: =BS320 -> 0 | BV19: Queretaro | BX19: =DE320 -> 0 | BY19: =DF320 -> 0 | BZ19: =DG320 -> 0 | CA19: =DH320 -> 0 | CB19: =DI320 -> 0 | CC19: =DJ320 -> 0 | CD19: =DK320 -> 0 | CE19: =DL320 -> 0 | ... DA19: =EH320 -> 0 | EJ19: Queretaro | EK19: =EK336 -> 0 | EL19: =EL336 -> 0 | EM19: =EM336 -> 0 | EN19: =EN336 -> 0 | EO19: =EO336 -> 0 | EP19: =EP336 -> 0 | EQ19: =EQ336 -> 0 | ER19: =ER336 -> 0 | ... FN19: =FN336 -> 0
A20: Puebla Sur | C20: =AM408 -> 0 | D20: =AN408 -> 0 | E20: =D20/C20 -> #DIV/0! | F20: =AP408 -> 0 | G20: =AQ408 -> 0 | H20: =AR408 -> 0 | I20: =AS408 -> 0 | J20: =AT408 -> 0 | K20: =AU408 -> 0 | L20: =AV408 -> 0 | M20: =AW408 -> 0 | ... AI20: =BS408 -> 0 | BV20: Tijuna | BX20: =DE408 -> 0 | BY20: =DF408 -> 0 | BZ20: =DG408 -> 0 | CA20: =DH408 -> 0 | CB20: =DI408 -> 0 | CC20: =DJ408 -> 0 | CD20: =DK408 -> 0 | CE20: =DL408 -> 0 | ... DA20: =EH408 -> 0 | EJ20: Tijuna | EK20: =EK424 -> 0 | EL20: =EL424 -> 0 | EM20: =EM424 -> 0 | EN20: =EN424 -> 0 | EO20: =EO424 -> 0 | EP20: =EP424 -> 0 | EQ20: =EQ424 -> 0 | ER20: =ER424 -> 0 | ... FN20: =FN424 -> 0
A21: Toluca | C21: =AM342 -> 0 | D21: =AN342 -> 0 | E21: =D21/C21 -> #DIV/0! | F21: =AP342 -> 0 | G21: =AQ342 -> 0 | H21: =AR342 -> 0 | I21: =AS342 -> 0 | J21: =AT342 -> 0 | K21: =AU342 -> 0 | L21: =AV342 -> 0 | M21: =AW342 -> 0 | ... AI21: =BS342 -> 0 | BV21: Toluca | BX21: =DE342 -> 0 | BY21: =DF342 -> 0 | BZ21: =DG342 -> 0 | CA21: =DH342 -> 0 | CB21: =DI342 -> 0 | CC21: =DJ342 -> 0 | CD21: =DK342 -> 0 | CE21: =DL342 -> 0 | ... DA21: =EH342 -> 0 | EJ21: Toluca | EK21: =EK358 -> 0 | EL21: =EL358 -> 0 | EM21: =EM358 -> 0 | EN21: =EN358 -> 0 | EO21: =EO358 -> 0 | EP21: =EP358 -> 0 | EQ21: =EQ358 -> 0 | ER21: =ER358 -> 0 | ... FN21: =FN358 -> 0
A22: Vallejo | C22: =AM364 -> 0 | D22: =AN364 -> 0 | E22: =D22/C22 -> #DIV/0! | F22: =AP364 -> 0 | G22: =AQ364 -> 0 | H22: =AR364 -> 0 | I22: =AS364 -> 0 | J22: =AT364 -> 0 | K22: =AU364 -> 0 | L22: =AV364 -> 0 | M22: =AW364 -> 0 | ... AI22: =BS364 -> 0 | BV22: Vallejo | BX22: =DE364 -> 0 | BY22: =DF364 -> 0 | BZ22: =DG364 -> 0 | CA22: =DH364 -> 0 | CB22: =DI364 -> 0 | CC22: =DJ364 -> 0 | CD22: =DK364 -> 0 | CE22: =DL364 -> 0 | ... DA22: =EH364 -> 0 | EJ22: Vallejo | EK22: =EK380 -> 0 | EL22: =EL380 -> 0 | EM22: =EM380 -> 0 | EN22: =EN380 -> 0 | EO22: =EO380 -> 0 | EP22: =EP380 -> 0 | EQ22: =EQ380 -> 0 | ER22: =ER380 -> 0 | ... FN22: =FN380 -> 0
A23: Veracruz | C23: =AM386 -> 0 | D23: =AN386 -> 0 | E23: =D23/C23 -> #DIV/0! | F23: =AP386 -> 0 | G23: =AQ386 -> 0 | H23: =AR386 -> 0 | I23: =AS386 -> 0 | J23: =AT386 -> 0 | K23: =AU386 -> 0 | L23: =AV386 -> 0 | M23: =AW386 -> 0 | ... AI23: =BS386 -> 0 | BV23: Veracruz | BX23: =DE386 -> 0 | BY23: =DF386 -> 0 | BZ23: =DG386 -> 0 | CA23: =DH386 -> 0 | CB23: =DI386 -> 0 | CC23: =DJ386 -> 0 | CD23: =DK386 -> 0 | CE23: =DL386 -> 0 | ... DA23: =EH386 -> 0 | EJ23: Veracruz | EK23: =EK402 -> 0 | EL23: =EL402 -> 0 | EM23: =EM402 -> 0 | EN23: =EN402 -> 0 | EO23: =EO402 -> 0 | EP23: =EP402 -> 0 | EQ23: =EQ402 -> 0 | ER23: =ER402 -> 0 | ... FN23: =FN402 -> 0
B24: Total | C24: =SUM(C7:C23) -> 0 | D24: =SUM(D7:D23) -> 0 | E24: =D24/C24 -> #DIV/0! | F24: =SUM(F7:F23) -> 0 | H24: =SUM(H7:H23) -> 0 | I24: =SUM(I7:I23) -> 0 | J24: =SUM(J7:J23) -> 0 | K24: =SUM(K7:K23) -> 0 | L24: =SUM(L7:L23) -> 0 | N24: =SUM(N7:N23) -> 0 | O24: =SUM(O7:O23) -> 0 | P24: =SUM(P7:P23) -> 0 | T24: =SUM(F24:P24) -> 0 | U24: =SUM(U7:U23) -> 0 | V24: =SUM(V7:V23) -> 0 | W24: =SUM(W7:W23) -> 0 | X24: =SUM(X7:X23) -> 0 | Y24: =SUM(Y7:Y23) -> 0 | Z24: =SUM(Z7:Z23) -> 0 | AA24: =SUM(AA7:AA23) -> 0 | AB24: =SUM(AB7:AB23) -> 0 | ... AI24: =SUM(AI7:AI23) -> 0 | AJ24: =AVERAGE(AJ7:AJ22) -> #DIV/0! | AK24: =AVERAGE(AK7:AK22) -> #DIV/0! | BW24: Total | BX24: =SUM(BX7:BX23) -> 0 | BZ24: =SUM(BZ7:BZ23) -> 0 | CA24: =SUM(CA7:CA23) -> 0 | CB24: =SUM(CB7:CB23) -> 0 | CC24: =SUM(CC7:CC23) -> 0 | CD24: =SUM(CD7:CD23) -> 0 | CF24: =SUM(CF7:CF23) -> 0 | CG24: =SUM(CG7:CG23) -> 0 | CH24: =SUM(CH7:CH23) -> 0 | CL24: =SUM(BX24:CH24) -> 0 | CM24: =SUM(CM7:CM22) -> 0 | CN24: =SUM(CN7:CN22) -> 0 | CO24: =SUM(CO7:CO22) -> 0 | CP24: =SUM(CP7:CP22) -> 0 | CQ24: =SUM(CQ7:CQ22) -> 0 | CR24: =SUM(CR7:CR22) -> 0 | CS24: =SUM(CS7:CS22) -> 0 | CT24: =SUM(CT7:CT22) -> 0 | ... DA24: =SUM(DA7:DA22) -> 0
C25: Costo de Oportunidad | F25: =SUM(T7:T23) -> 0 | BX25: =SUM(CL7:CL22) -> 0
A27: Concentrado por Tienda de Dictamen de Auditoria de Dummy | BV27: Recuperación por tienda y rubro
F30: Causas de Negado | U30: Incidencias de Auditoria | BX30: Causas de Negado | CM30: Incidencias de Auditoria
A31: Tiendas | B31: Ropa | C31: Tallas por pasillo | D31: Tallas por modelo | E31: % de Cobertura de auditoria | F31: Frenteos | G31: Ubicación Revuelta | H31: Bodega Venta (Sin marcar) | I31: Bodega Tapanco | J31: Doble Ubicación | K31: Excedente | L31: Origen | M31: Cambios/Probadores | N31: Negados Sin Recuperar | O31: Exhibición | P31: Bodega Aclaración | Q31: Aduanas | R31: Golden o apartados | S31: Control de calidad | T31: Costo por pasillo | U31: Sin Exhibición | V31: Exhibición fuera de Política | W31: Modelos revuelto | X31: Modelos mal entallados | Y31: Modelos con error de ubicación | Z31: Curva con diferencia en frentes | AA31: Curva con diferencia en fondos | AB31: Curva con diferencia en altura | AC31: Curvas vencidas | AD31: Curvas que no coincide Price Soft vs Piso de Venta | AE31: Curvas faltantes | AF31: Cenefas faltantes | AG31: Cenefas de precio Promoción faltantes | AH31: Cartas disculpa / destallados faltantes | AI31: Fechas de llegada faltantes | BV31: Tiendas | BW31: Responsable de Catalogo | BX31: Frenteos | BY31: Ubicación Revuelta | BZ31: Bodega Venta (Sin marcar) | CA31: Bodega Tapanco | CB31: Doble Ubicación | CC31: Excedente | CD31: Origen | CE31: Cambios/Probadores | CF31: Negados Sin Recuperar | CG31: Exhibición | CH31: Bodega Aclaración | CI31: Aduanas | CJ31: Golden o apartados | CK31: Control de calidad | CL31: Costo por pasillo | CM31: Sin Exhibición | CN31: Exhibición fuera de Política | CO31: Modelos revuelto | CP31: Modelos mal entallados | CQ31: Modelos con error de ubicación | CR31: Curva con diferencia en frentes | CS31: Curva con diferencia en fondos | CT31: Curva con diferencia en altura | CU31: Curvas vencidas | CV31: Curvas que no coincide Price Soft vs Piso de Venta | CW31: Curvas faltantes | CX31: Cenefas faltantes | CY31: Cenefas de precio Promoción faltantes | CZ31: Cartas disculpa / destallados faltantes | DA31: Fechas de llegada faltantes | EK31: Frenteos | EL31: Ubicación Revuelta | EM31: Bodega Venta (Sin marcar) | EN31: Bodega Tapanco | EO31: Doble Ubicación | EP31: Excedente | EQ31: Origen | ER31: Cambios/Probadores | ES31: Negados Sin Recuperar | ET31: Exhibición | EU31: Bodega Aclaración | EV31: Aduanas | EW31: Golden o apartados | EX31: Control de calidad | EZ31: Frenteos | FA31: Ubicación Revuelta | FB31: Bodega Venta (Sin marcar) | FC31: Bodega Tapanco | FD31: Doble Ubicación | FE31: Excedente | FF31: Origen | FG31: Cambios/Probadores | FH31: Negados Sin Recuperar | FI31: Exhibición | FJ31: Bodega Aclaración | FK31: Aduanas | FL31: Golden o apartados | FM31: Control de calidad
A32: Aguascalientes | C32: =AM58 -> 0 | D32: =AN58 -> 0 | E32: =D32/C32 -> #DIV/0! | F32: =AP58 -> 0 | G32: =AQ58 -> 0 | H32: =AR58 -> 0 | I32: =AS58 -> 0 | J32: =AT58 -> 0 | K32: =AU58 -> 0 | L32: =AV58 -> 0 | M32: =AW58 -> 0 | ... AI32: =BS58 -> 0 | BV32: Aguascalientes | BX32: =DE58 -> 0 | BY32: =DF58 -> 0 | BZ32: =DG58 -> 0 | CA32: =DH58 -> 0 | CB32: =DI58 -> 0 | CC32: =DJ58 -> 0 | CD32: =DK58 -> 0 | CE32: =DL58 -> 0 | ... DA32: =EH58 -> 0 | EJ32: Aguascalientes | EK32: =EK73 -> 0 | EL32: =EL73 -> 0 | EM32: =EM73 -> 0 | EN32: =EN73 -> 0 | EO32: =EO73 -> 0 | EP32: =EP73 -> 0 | EQ32: =EQ73 -> 0 | ER32: =ER73 -> 0 | ... FN32: =FN73 -> 0
A33: Arco Norte | C33: =AM80 -> 0 | D33: =AN80 -> 0 | E33: =D33/C33 -> #DIV/0! | F33: =AP80 -> 0 | G33: =AQ80 -> 0 | H33: =AR80 -> 0 | I33: =AS80 -> 0 | J33: =AT80 -> 0 | K33: =AU80 -> 0 | L33: =AV80 -> 0 | M33: =AW80 -> 0 | ... AI33: =BS80 -> 0 | BV33: Arco Norte | BX33: =DE80 -> 0 | BY33: =DF80 -> 0 | BZ33: =DG80 -> 0 | CA33: =DH80 -> 0 | CB33: =DI80 -> 0 | CC33: =DJ80 -> 0 | CD33: =DK80 -> 0 | CE33: =DL80 -> 0 | ... DA33: =EH80 -> 0 | EJ33: Arco Norte | EK33: =EK95 -> 0 | EL33: =EL95 -> 0 | EM33: =EM95 -> 0 | EN33: =EN95 -> 0 | EO33: =EO95 -> 0 | EP33: =EP95 -> 0 | EQ33: =EQ95 -> 0 | ER33: =ER95 -> 0 | ... FN33: =FN95 -> 0
A34: Centro Historico | C34: =AM102 -> 0 | D34: =AN102 -> 0 | E34: =D34/C34 -> #DIV/0! | F34: =AP102 -> 0 | G34: =AQ102 -> 0 | H34: =AR102 -> 0 | I34: =AS102 -> 0 | J34: =AT102 -> 0 | K34: =AU102 -> 0 | L34: =AV102 -> 0 | M34: =AW102 -> 0 | ... AI34: =BS102 -> 0 | BV34: Centro Historico | BX34: =DE102 -> 0 | BY34: =DF102 -> 0 | BZ34: =DG102 -> 0 | CA34: =DH102 -> 0 | CB34: =DI102 -> 0 | CC34: =DJ102 -> 0 | CD34: =DK102 -> 0 | CE34: =DL102 -> 0 | ... DA34: =EH102 -> 0 | EJ34: Centro Historico | EK34: =EK117 -> 0 | EL34: =EL117 -> 0 | EM34: =EM117 -> 0 | EN34: =EN117 -> 0 | EO34: =EO117 -> 0 | EP34: =EP117 -> 0 | EQ34: =EQ117 -> 0 | ER34: =ER117 -> 0 | ... FN34: =FN117 -> 0
A35: Ecatepec | C35: =AM124 -> 0 | D35: =AN124 -> 0 | E35: =D35/C35 -> #DIV/0! | F35: =AP124 -> 0 | G35: =AQ124 -> 0 | H35: =AR124 -> 0 | I35: =AS124 -> 0 | J35: =AT124 -> 0 | K35: =AU124 -> 0 | L35: =AV124 -> 0 | M35: =AW124 -> 0 | ... AI35: =BS124 -> 0 | BV35: Ecatepec | BX35: =DE124 -> 0 | BY35: =DF124 -> 0 | BZ35: =DG124 -> 0 | CA35: =DH124 -> 0 | CB35: =DI124 -> 0 | CC35: =DJ124 -> 0 | CD35: =DK124 -> 0 | CE35: =DL124 -> 0 | ... DA35: =EH124 -> 0 | EJ35: Ecatepec | EK35: =EK139 -> 0 | EL35: =EL139 -> 0 | EM35: =EM139 -> 0 | EN35: =EN139 -> 0 | EO35: =EO139 -> 0 | EP35: =EP139 -> 0 | EQ35: =EQ139 -> 0 | ER35: =ER139 -> 0 | ... FN35: =FN139 -> 0
A36: Guadalajara | C36: =AM146 -> 0 | D36: =AN146 -> 0 | E36: =D36/C36 -> #DIV/0! | F36: =AP146 -> 0 | G36: =AQ146 -> 0 | H36: =AR146 -> 0 | I36: =AS146 -> 0 | J36: =AT146 -> 0 | K36: =AU146 -> 0 | L36: =AV146 -> 0 | M36: =AW146 -> 0 | ... AI36: =BS146 -> 0 | BV36: Guadalajara | BX36: =DE146 -> 0 | BY36: =DF146 -> 0 | BZ36: =DG146 -> 0 | CA36: =DH146 -> 0 | CB36: =DI146 -> 0 | CC36: =DJ146 -> 0 | CD36: =DK146 -> 0 | CE36: =DL146 -> 0 | ... DA36: =EH146 -> 0 | EJ36: Guadalajara | EK36: =EK161 -> 0 | EL36: =EL161 -> 0 | EM36: =EM161 -> 0 | EN36: =EN161 -> 0 | EO36: =EO161 -> 0 | EP36: =EP161 -> 0 | EQ36: =EQ161 -> 0 | ER36: =ER161 -> 0 | ... FN36: =FN161 -> 0
A37: Ixtapaluca | C37: =AM168 -> 0 | D37: =AN168 -> 0 | E37: =D37/C37 -> #DIV/0! | F37: =AP168 -> 0 | G37: =AQ168 -> 0 | H37: =AR168 -> 0 | I37: =AS168 -> 0 | J37: =AT168 -> 0 | K37: =AU168 -> 0 | L37: =AV168 -> 0 | M37: =AW168 -> 0 | ... AI37: =BS168 -> 0 | BV37: Ixtapaluca | BX37: =DE168 -> 0 | BY37: =DF168 -> 0 | BZ37: =DG168 -> 0 | CA37: =DH168 -> 0 | CB37: =DI168 -> 0 | CC37: =DJ168 -> 0 | CD37: =DK168 -> 0 | CE37: =DL168 -> 0 | ... DA37: =EH168 -> 0 | EJ37: Ixtapaluca | EK37: =EK183 -> 0 | EL37: =EL183 -> 0 | EM37: =EM183 -> 0 | EN37: =EN183 -> 0 | EO37: =EO183 -> 0 | EP37: =EP183 -> 0 | EQ37: =EQ183 -> 0 | ER37: =ER183 -> 0 | ... FN37: =FN183 -> 0
A38: Iztapalapa | C38: =AM190 -> 0 | D38: =AN190 -> 0 | E38: =D38/C38 -> #DIV/0! | F38: =AP190 -> 0 | G38: =AQ190 -> 0 | H38: =AR190 -> 0 | I38: =AS190 -> 0 | J38: =AT190 -> 0 | K38: =AU190 -> 0 | L38: =AV190 -> 0 | M38: =AW190 -> 0 | ... AI38: =BS190 -> 0 | BV38: Iztapalapa | BX38: =DE190 -> 0 | BY38: =DF190 -> 0 | BZ38: =DG190 -> 0 | CA38: =DH190 -> 0 | CB38: =DI190 -> 0 | CC38: =DJ190 -> 0 | CD38: =DK190 -> 0 | CE38: =DL190 -> 0 | ... DA38: =EH190 -> 0 | EJ38: Iztapalapa | EK38: =EK205 -> 0 | EL38: =EL205 -> 0 | EM38: =EM205 -> 0 | EN38: =EN205 -> 0 | EO38: =EO205 -> 0 | EP38: =EP205 -> 0 | EQ38: =EQ205 -> 0 | ER38: =ER205 -> 0 | ... FN38: =FN205 -> 0
A39: León | C39: =AM212 -> 0 | D39: =AN212 -> 0 | E39: =D39/C39 -> #DIV/0! | F39: =AP212 -> 0 | G39: =AQ212 -> 0 | H39: =AR212 -> 0 | I39: =AS212 -> 0 | J39: =AT212 -> 0 | K39: =AU212 -> 0 | L39: =AV212 -> 0 | M39: =AW212 -> 0 | ... AI39: =BS212 -> 0 | BV39: León | BX39: =DE212 -> 0 | BY39: =DF212 -> 0 | BZ39: =DG212 -> 0 | CA39: =DH212 -> 0 | CB39: =DI212 -> 0 | CC39: =DJ212 -> 0 | CD39: =DK212 -> 0 | CE39: =DL212 -> 0 | ... DA39: =EH212 -> 0 | EJ39: León | EK39: =EK227 -> 0 | EL39: =EL227 -> 0 | EM39: =EM227 -> 0 | EN39: =EN227 -> 0 | EO39: =EO227 -> 0 | EP39: =EP227 -> 0 | EQ39: =EQ227 -> 0 | ER39: =ER227 -> 0 | ... FN39: =FN227 -> 0
A40: Miravalle | C40: =AM234 -> 0 | D40: =AN234 -> 0 | E40: =D40/C40 -> #DIV/0! | F40: =AP234 -> 0 | G40: =AQ234 -> 0 | H40: =AR234 -> 0 | I40: =AS234 -> 0 | J40: =AT234 -> 0 | K40: =AU234 -> 0 | L40: =AV234 -> 0 | M40: =AW234 -> 0 | ... AI40: =BS234 -> 0 | BV40: Miravalle | BX40: =DE234 -> 0 | BY40: =DF234 -> 0 | BZ40: =DG234 -> 0 | CA40: =DH234 -> 0 | CB40: =DI234 -> 0 | CC40: =DJ234 -> 0 | CD40: =DK234 -> 0 | CE40: =DL234 -> 0 | ... DA40: =EH234 -> 0 | EJ40: Miravalle | EK40: =EK249 -> 0 | EL40: =EL249 -> 0 | EM40: =EM249 -> 0 | EN40: =EN249 -> 0 | EO40: =EO249 -> 0 | EP40: =EP249 -> 0 | EQ40: =EQ249 -> 0 | ER40: =ER249 -> 0 | ... FN40: =FN249 -> 0
A41: Naucalpan | C41: =AM256 -> 0 | D41: =AN256 -> 0 | E41: =D41/C41 -> #DIV/0! | F41: =AP256 -> 0 | G41: =AQ256 -> 0 | H41: =AR256 -> 0 | I41: =AS256 -> 0 | J41: =AT256 -> 0 | K41: =AU256 -> 0 | L41: =AV256 -> 0 | M41: =AW256 -> 0 | ... AI41: =BS256 -> 0 | BV41: Naucalpan | BX41: =DE256 -> 0 | BY41: =DF256 -> 0 | BZ41: =DG256 -> 0 | CA41: =DH256 -> 0 | CB41: =DI256 -> 0 | CC41: =DJ256 -> 0 | CD41: =DK256 -> 0 | CE41: =DL256 -> 0 | ... DA41: =EH256 -> 0 | EJ41: Naucalpan | EK41: =EK271 -> 0 | EL41: =EL271 -> 0 | EM41: =EM271 -> 0 | EN41: =EN271 -> 0 | EO41: =EO271 -> 0 | EP41: =EP271 -> 0 | EQ41: =EQ271 -> 0 | ER41: =ER271 -> 0 | ... FN41: =FN271 -> 0
A42: Olivar del Conde | C42: =AM278 -> 0 | D42: =AN278 -> 0 | E42: =D42/C42 -> #DIV/0! | F42: =AP278 -> 0 | G42: =AQ278 -> 0 | H42: =AR278 -> 0 | I42: =AS278 -> 0 | J42: =AT278 -> 0 | K42: =AU278 -> 0 | L42: =AV278 -> 0 | M42: =AW278 -> 0 | ... AI42: =BS278 -> 0 | BV42: Olivar del Conde | BX42: =DE278 -> 0 | BY42: =DF278 -> 0 | BZ42: =DG278 -> 0 | CA42: =DH278 -> 0 | CB42: =DI278 -> 0 | CC42: =DJ278 -> 0 | CD42: =DK278 -> 0 | CE42: =DL278 -> 0 | ... DA42: =EH278 -> 0 | EJ42: Olivar del Conde | EK42: =EK293 -> 0 | EL42: =EL293 -> 0 | EM42: =EM293 -> 0 | EN42: =EN293 -> 0 | EO42: =EO293 -> 0 | EP42: =EP293 -> 0 | EQ42: =EQ293 -> 0 | ER42: =ER293 -> 0 | ... FN42: =FN293 -> 0
A43: Puebla | C43: =AM300 -> 0 | D43: =AN300 -> 0 | E43: =D43/C43 -> #DIV/0! | F43: =AP300 -> 0 | G43: =AQ300 -> 0 | H43: =AR300 -> 0 | I43: =AS300 -> 0 | J43: =AT300 -> 0 | K43: =AU300 -> 0 | L43: =AV300 -> 0 | M43: =AW300 -> 0 | ... AI43: =BS300 -> 0 | BV43: Puebla | BX43: =DE300 -> 0 | BY43: =DF300 -> 0 | BZ43: =DG300 -> 0 | CA43: =DH300 -> 0 | CB43: =DI300 -> 0 | CC43: =DJ300 -> 0 | CD43: =DK300 -> 0 | CE43: =DL300 -> 0 | ... DA43: =EH300 -> 0 | EJ43: Puebla | EK43: =EK315 -> 0 | EL43: =EL315 -> 0 | EM43: =EM315 -> 0 | EN43: =EN315 -> 0 | EO43: =EO315 -> 0 | EP43: =EP315 -> 0 | EQ43: =EQ315 -> 0 | ER43: =ER315 -> 0 | ... FN43: =FN315 -> 0
A44: Queretaro | C44: =AM322 -> 0 | D44: =AN322 -> 0 | E44: =D44/C44 -> #DIV/0! | F44: =AP322 -> 0 | G44: =AQ322 -> 0 | H44: =AR322 -> 0 | I44: =AS322 -> 0 | J44: =AT322 -> 0 | K44: =AU322 -> 0 | L44: =AV322 -> 0 | M44: =AW322 -> 0 | ... AI44: =BS322 -> 0 | BV44: Queretaro | BX44: =DE322 -> 0 | BY44: =DF322 -> 0 | BZ44: =DG322 -> 0 | CA44: =DH322 -> 0 | CB44: =DI322 -> 0 | CC44: =DJ322 -> 0 | CD44: =DK322 -> 0 | CE44: =DL322 -> 0 | ... DA44: =EH322 -> 0 | EJ44: Queretaro | EK44: =EK337 -> 0 | EL44: =EL337 -> 0 | EM44: =EM337 -> 0 | EN44: =EN337 -> 0 | EO44: =EO337 -> 0 | EP44: =EP337 -> 0 | EQ44: =EQ337 -> 0 | ER44: =ER337 -> 0 | ... FN44: =FN337 -> 0
A45: Puebla Sur | C45: =AM410 -> 0 | D45: =AN410 -> 0 | E45: =D45/C45 -> #DIV/0! | F45: =AP410 -> 0 | G45: =AQ410 -> 0 | H45: =AR410 -> 0 | I45: =AS410 -> 0 | J45: =AT410 -> 0 | K45: =AU410 -> 0 | L45: =AV410 -> 0 | M45: =AW410 -> 0 | ... AI45: =BS410 -> 0 | BV45: Tijuna | BX45: =DE410 -> 0 | BY45: =DF410 -> 0 | BZ45: =DG410 -> 0 | CA45: =DH410 -> 0 | CB45: =DI410 -> 0 | CC45: =DJ410 -> 0 | CD45: =DK410 -> 0 | CE45: =DL410 -> 0 | ... DA45: =EH410 -> 0 | EJ45: Tijuna | EK45: =EK425 -> 0 | EL45: =EL425 -> 0 | EM45: =EM425 -> 0 | EN45: =EN425 -> 0 | EO45: =EO425 -> 0 | EP45: =EP425 -> 0 | EQ45: =EQ425 -> 0 | ER45: =ER425 -> 0 | ... FN45: =FN425 -> 0
...

Sheet Concentrado 
B2: Concentrado por Tienda de Dictamen de Auditoria de Dummy de Calzado | BU2: Concentrado por Tienda de Dictamen de Auditoria de Dummy de Calzado | CW2: Concentrado por Tienda de Dictamen de Auditoria Administrativa | EV2: Negado de frenteo | FI2: Negado de revueltos | FV2: Negado de Bodega | GI2: Negado de Bodega tapanco | GV2: Negado de Doble ubicacion | HI2: Negado de Excedente | HV2: Negado de origen | II2: Negado de Cambios/Probadores | IV2: Negados Negados Sin Recuperar | JI2: Negado de Exhibicion | JV2: Negado de Bodega Aclaración | KI2: Negado de Aduanas | KV2: Negado de Golden o Apartados | LI2: Negado de Control de Calidad
X3: =SEMANA!J3 -> "Semana " | AA3: =SEMANA!Y3 -> 0 | CJ3: =X3 -> "Semana " | DE3: Semana: | DM3: =X3 -> "Semana "
B5: Auditoria de Calzado | H5: Causas de Negado | BU5: Auditoria de Calzado | CA5: Estandares operativos | CW5: Auditoria de Calzado | DA5: Incidencias | EV5: Auditoria de Calzado | FB5: Causas de Negado | FI5: Auditoria de Calzado | FO5: Causas de Negado | FV5: Auditoria de Calzado | GB5: Causas de Negado | GI5: Auditoria de Calzado | GO5: Causas de Negado | GV5: Auditoria de Calzado | HB5: Causas de Negado | HI5: Auditoria de Calzado | HO5: Causas de Negado | HV5: Auditoria de Calzado | IB5: Causas de Negado | II5: Auditoria de Calzado | IO5: Causas de Negado | IV5: Auditoria de Calzado | JB5: Causas de Negado | JI5: Auditoria de Calzado | JO5: Causas de Negado | JV5: Auditoria de Calzado | KB5: Causas de Negado | KI5: Auditoria de Calzado | KO5: Causas de Negado | KV5: Auditoria de Calzado | LB5: Causas de Negado | LI5: Auditoria de Calzado | LO5: Causas de Negado
